Workbook

Sheet Sheet2
B1: INPUT
B2: 입력1 | C2: 전용 면적 (평)
B3: 전용 면적(평) (선택) | C3: 32
B4: 히트펌프 열용량(kW) | C4: =IF(C3<=14,8,IF(C3<=25,12,IF(C3<=40,16,20))) -> 16
B5: 필요 공간 | C5: =IF(C3<=14,"냉장고 크기", IF(C3<=25,"워시타워 설치 공간",IF(C3<=35,"보일러실 공간","보일러실 공간 이상"))) -> 보일러실 공간
B7: 입력2 | C7: 현재 난방기기
B8: 난방기기(선택) | C8: 가스 콘덴싱보일러 | E8: 가스 콘덴싱보일러 | F8: 가스 일반보일러 | G8: 등유 보일러 | H8: LPG 보일러 | I8: 히트펌프(2025년) | J8: 히트펌프(2038년)
B9: 기기 효율 | E9: 0.92 | F9: 0.83 | G9: 0.82 | H9: 0.9 | I9: =O51*100% -> 2.8619392 | J9: =O51*100% -> 2.8619392
B10: 기기 온실가스 배출계수(tCO2eq/MWh) | E10: 0.21847826 | F10: 0.24216867 | G10: 0.30634828 | H10: 0.25555556 | I10: =0.4173/I9 -> 0.14581023 | J10: =(83.1/624.5)/J9 -> 0.046495207
B12: 입력3 | C12: 취사기기
B13: 취사기기(선택) | C13: 인덕션(전기) | E13: 도시가스 | F13: LPG | G13: 인덕션(전기)
B14: 전체 사용량 대비 난방 비중 | C14: =IF(OR(TRIM(C13)="도시가스",TRIM(C13)="LPG"),84.75%,100%) -> 1
B16: 입력4 | C16: 난방요금 | D16: 주) 1월만 입력하게 하고 월별 난방비중으로 추정
C17: 1월 | D17: 2월 | E17: 3월 | F17: 4월 | G17: 5월 | H17: 6월 | I17: 7월 | J17: 8월 | K17: 9월 | L17: 10월 | M17: 11월 | N17: 12월 | O17: 계
B18: 월별 난방요금(입력) | C18: 300000 | D18: =$C$18/$C$20*D20 -> 275767.18 | E18: =$C$18/$C$20*E20 -> 237111.22 | F18: =$C$18/$C$20*F20 -> 111382.24 | G18: =$C$18/$C$20*G20 -> 73454.72 | H18: =$C$18/$C$20*H20 -> 57283.321 | I18: =$C$18/$C$20*I20 -> 41403.298 | J18: =$C$18/$C$20*J20 -> 42180.302 | K18: =$C$18/$C$20*K20 -> 66413.12 | ... N18: =$C$18/$C$20*N20 -> 200125.64 | O18: =SUM(C18:N18) -> 1620551.6
B19: 지역 (선택) | C19: 전라북도 | D19: 전주시
B20: 월별 난방비중 | C20: =_xlfn.XLOOKUP($C$19, Sheet3!$A$2:$A$19, Sheet3!C$2:C$19, "") -> 0.18512215 | D20: =_xlfn.XLOOKUP($C$19, Sheet3!$A$2:$A$19, Sheet3!D$2:D$19, "") -> 0.17016871 | E20: =_xlfn.XLOOKUP($C$19, Sheet3!$A$2:$A$19, Sheet3!E$2:E$19, "") -> 0.14631513 | F20: =_xlfn.XLOOKUP($C$19, Sheet3!$A$2:$A$19, Sheet3!F$2:F$19, "") -> 0.068731063 | G20: =_xlfn.XLOOKUP($C$19, Sheet3!$A$2:$A$19, Sheet3!G$2:G$19, "") -> 0.045326986 | H20: =_xlfn.XLOOKUP($C$19, Sheet3!$A$2:$A$19, Sheet3!H$2:H$19, "") -> 0.035348038 | I20: =_xlfn.XLOOKUP($C$19, Sheet3!$A$2:$A$19, Sheet3!I$2:I$19, "") -> 0.025548892 | J20: =_xlfn.XLOOKUP($C$19, Sheet3!$A$2:$A$19, Sheet3!J$2:J$19, "") -> 0.026028361 | ... N20: =_xlfn.XLOOKUP($C$19, Sheet3!$A$2:$A$19, Sheet3!N$2:N$19, "") -> 0.1234923
B22: 입력5 | C22: 전기요금 | D22: 주) 1월만 입력하게 하고 월별 난방비중으로 추정
C23: 1월 | D23: 2월 | E23: 3월 | F23: 4월 | G23: 5월 | H23: 6월 | I23: 7월 | J23: 8월 | K23: 9월 | L23: 10월 | M23: 11월 | N23: 12월
B24: 월별 전기사용량(입력) | C24: 1500 | D24: =$C$24/$C$25*D25 -> 1510.5769 | E24: =$C$24/$C$25*E25 -> 1313.2115 | F24: =$C$24/$C$25*F25 -> 1318.2304 | G24: =$C$24/$C$25*G25 -> 1237.326 | H24: =$C$24/$C$25*H25 -> 1319.5808 | I24: =$C$24/$C$25*I25 -> 1697.9813 | J24: =$C$24/$C$25*J25 -> 2133.4285 | K24: =$C$24/$C$25*K25 -> 1963.8835 | ... N24: =$C$24/$C$25*N25 -> 1380.746 | O24: =SUM(C24:N24) -> 18090.444
B25: 월별 전기요금 비중 | C25: 0.082916702 | D25: 0.083501369 | E25: 0.072591447 | F25: 0.072868879 | G25: 0.068396663 | H25: 0.072943525 | I25: 0.093860674 | J25: 0.11793124 | K25: 0.10855916 | L25: 0.076865317 | M25: 0.073240423 | N25: 0.076324601
B27: 입력6 | C27: 태양광
B28: 태양광 설치 유무(선택) | C28: 유/무
B29: 설치 용량(입력)(kW) | C29: 0
B32: OUTPUT
B33: 결과1 | C33: TCO
C34: 도시가스(콘덴싱) | D34: 전기
B35: 설치비(원) | C35: 1000000 | D35: 10000000
B36: 보조금(%) | D36: 0.7
B37: 순 비용(원) | D37: =D35*(1-D36) -> 3000000
B39: 요금 체계(부가세 포함) | C39: 도시가스(콘덴싱) | D39: 도시가스(일반) | E39: 등유 | F39: LPG
B40: 기본요금(원) | C40: =1250*1.1 -> 1375 | D40: =1250*1.1 -> 1375 | E40: 0 | F40: 0
B41: 사용요금(기존 단위)(가스: 원/MJ, 등유: 원/L, LPG: 원/kg) | C41: =22.3617*1.1 -> 24.59787 | D41: =22.3617*1.1 -> 24.59787 | E41: 1323.16 | F41: 1417.54
B42: 사용요금(원/KWh) | C42: =C41*3.6 -> 88.552332 | D42: =D41*3.6 -> 88.552332 | E42: =E41/(D86/3.6) -> 130.14689 | F42: =F41/(D87/3.6) -> 101.65625
B43: 실제 난방 에너지 사용량(kWh) | C43: =((O18-C40*12)/C42)*C14 -> 18114.166 | D43: =((O18-D40*12)/D42)*C14 -> 18114.166 | E43: =($O$18/E42) -> 12451.713 | F43: =($O$18/F42) -> 15941.485
B44: 유효 열 수요(kWh)(히트펌프 전환 계산용) | C44: =(((O18-C40*12)/C42)*C14)*E9 -> 16665.033 | D44: =(((O18-D40*12)/D42)*C14)*F9 -> 15034.758 | E44: =($O$18/E42)*G9 -> 10210.404 | F44: =($O$18/F42)*H9 -> 14347.336
C45: 1월 | D45: 2월 | E45: 3월 | F45: 4월 | G45: 5월 | H45: 6월 | I45: 7월 | J45: 8월 | K45: 9월 | L45: 10월 | M45: 11월 | N45: 12월
B46: 도시가스(컨덴싱) | C46: =$C$44*C$20 -> 3085.0666 | D46: =$C$44*D$20 -> 2835.8671 | E46: =$C$44*E$20 -> 2438.3464 | F46: =$C$44*F$20 -> 1145.4054 | G46: =$C$44*G$20 -> 755.37569 | H46: =$C$44*H$20 -> 589.07621 | I46: =$C$44*I$20 -> 425.77311 | J46: =$C$44*J$20 -> 433.76348 | ... N46: =$C$44*N$20 -> 2058.0031
B47: 도시가스(일반) | C47: =$D$44*C$20 -> 2783.2666 | D47: =$D$44*D$20 -> 2558.4453 | E47: =$D$44*E$20 -> 2199.8125 | F47: =$D$44*F$20 -> 1033.3549 | G47: =$D$44*G$20 -> 681.48024 | H47: =$D$44*H$20 -> 531.44919 | I47: =$D$44*I$20 -> 384.12139 | J47: =$D$44*J$20 -> 391.33009 | ... N47: =$D$44*N$20 -> 1856.6768
B48: 등유 | C48: =$E$44*C$20 -> 1890.172 | D48: =$E$44*D$20 -> 1737.4914 | E48: =$E$44*E$20 -> 1493.9367 | F48: =$E$44*F$20 -> 701.77195 | G48: =$E$44*G$20 -> 462.80685 | H48: =$E$44*H$20 -> 360.91776 | I48: =$E$44*I$20 -> 260.86452 | J48: =$E$44*J$20 -> 265.76009 | ... N48: =$E$44*N$20 -> 1260.9063
...

Sheet Sheet3
A1: 지역 | B1: 구분 | C1: 1월 | D1: 2월 | E1: 3월 | F1: 4월 | G1: 5월 | H1: 6월 | I1: 7월 | J1: 8월 | K1: 9월 | L1: 10월 | M1: 11월 | N1: 12월
A2: 전국 | B2: 월별 비중(합계=1) | C2: 0.20529024 | D2: 0.19690434 | E2: 0.15276304 | F2: 0.090096652 | G2: 0.048884173 | H2: 0.030832675 | I2: 0.019948259 | J2: 0.01692641 | K2: 0.023031186 | L2: 0.03465798 | M2: 0.067692398 | N2: 0.11297265
A3: 서울특별시 | B3: 월별 비중(합계=1) | C3: 0.19641921 | D3: 0.19735821 | E3: 0.15533138 | F3: 0.098205927 | G3: 0.049145957 | H3: 0.029024122 | I3: 0.017598115 | J3: 0.015418844 | K3: 0.02033687 | L3: 0.034673004 | M3: 0.069518548 | N3: 0.11696981
A4: 부산광역시 | B4: 월별 비중(합계=2) | C4: 0.20296558 | D4: 0.19113091 | E4: 0.1407114 | F4: 0.086687505 | G4: 0.051980964 | H4: 0.033865165 | I4: 0.024416422 | J4: 0.022288616 | K4: 0.029174468 | L4: 0.040317695 | M4: 0.069694974 | N4: 0.1067663
A5: 대구광역시 | B5: 월별 비중(합계=3) | C5: 0.22711835 | D5: 0.21775169 | E5: 0.16064843 | F5: 0.099598217 | G5: 0.054080559 | H5: 0.032880615 | I5: 0.018593542 | J5: 0.012146451 | K5: 0.014277154 | L5: 0.020752134 | M5: 0.045812527 | N5: 0.096340326
A6: 인천광역시 | B6: 월별 비중(합계=4) | C6: 0.20927893 | D6: 0.22033979 | E6: 0.16379592 | F6: 0.093855063 | G6: 0.04789529 | H6: 0.027918998 | I6: 0.012901023 | J6: 0.010421865 | K6: 0.011187487 | L6: 0.02490216 | M6: 0.059573289 | N6: 0.11793018
A7: 광주광역시 | B7: 월별 비중(합계=5) | C7: 0.24781327 | D7: 0.1916139 | E7: 0.14460459 | F7: 0.081635571 | G7: 0.041774101 | H7: 0.03787872 | I7: 0.023204858 | J7: 0.023242678 | K7: 0.027169456 | L7: 0.029061844 | M7: 0.056223188 | N7: 0.095777823
A8: 대전광역시 | B8: 월별 비중(합계=6) | C8: 0.20506541 | D8: 0.20102171 | E8: 0.1723434 | F8: 0.094209632 | G8: 0.049968414 | H8: 0.025493416 | I8: 0.011766135 | J8: 0.0095314609 | K8: 0.019906732 | L8: 0.026903389 | M8: 0.061567434 | N8: 0.12222286
A9: 울산광역시 | B9: 월별 비중(합계=7) | C9: 0.20974003 | D9: 0.21558495 | E9: 0.16585522 | F9: 0.094119213 | G9: 0.054801748 | H9: 0.034743772 | I9: 0.015642269 | J9: 0.0094328975 | K9: 0.015872202 | L9: 0.023724661 | M9: 0.054514293 | N9: 0.10596875
A10: 세종특별자치시 | B10: 월별 비중(합계=8) | C10: 0.18966287 | D10: 0.17164657 | E10: 0.11859857 | F10: 0.081765248 | G10: 0.052738986 | H10: 0.031319606 | I10: 0.01590566 | J10: 0.013703667 | K10: 0.035923771 | L10: 0.062748042 | M10: 0.093575934 | N10: 0.13241107
A11: 경기도 | B11: 월별 비중(합계=9) | C11: 0.20265281 | D11: 0.19655864 | E11: 0.15868243 | F11: 0.079792199 | G11: 0.043627506 | H11: 0.028448588 | I11: 0.022362834 | J11: 0.018622825 | K11: 0.022112363 | L11: 0.034560079 | M11: 0.077122925 | N11: 0.1154568
A12: 강원도 | B12: 월별 비중(합계=10) | C12: 0.20253038 | D12: 0.24061994 | E12: 0.14477452 | F12: 0.12446143 | G12: 0.045634539 | H12: 0.0090103506 | I12: 0.024260323 | J12: 0.015943075 | K12: 0.015316502 | L12: 0.02528103 | M12: 0.056852213 | N12: 0.095315695
A13: 충청북도 | B13: 월별 비중(합계=11) | C13: 0.20021253 | D13: 0.17286216 | E13: 0.1129823 | F13: 0.067184975 | G13: 0.039718217 | H13: 0.027905184 | I13: 0.019467303 | J13: 0.017488765 | K13: 0.04693406 | L13: 0.067766898 | M13: 0.099539884 | N13: 0.12793772
... A19: 제주특별자치도 | B19: 월별 비중(합계=17) | C19: 0.17281166 | D19: 0.20172745 | E19: 0.08413655 | F19: 0.057148474 | G19: 0.053293034 | H19: 0.053293034 | I19: 0.028232678 | J19: 0.026304958 | K19: 0.034015837 | L19: 0.028232678 | M19: 0.093775148 | N19: 0.1670285

Sheet 목록
A1: 시도 | B1: 기초지자체
A2: 서울특별시 | B2: 종로구 | D2: {=_xlfn._xlws.SORT(_xlfn.UNIQUE(A2:A229))} -> 강원도 | E2: {=_xlfn._xlws.SORT(_xlfn._xlws.FILTER($B$2:$B$229,$A$2:$A$229=Sheet2!$C$19,""))} -> 고창군
A3: 서울특별시 | B3: 중구 | D3: 경기도 | E3: 군산시
A4: 서울특별시 | B4: 용산구 | D4: 경상남도 | E4: 김제시
A5: 서울특별시 | B5: 성동구 | D5: 경상북도 | E5: 남원시
A6: 서울특별시 | B6: 광진구 | D6: 광주광역시 | E6: 무주군
A7: 서울특별시 | B7: 동대문구 | D7: 대구광역시 | E7: 부안군
A8: 서울특별시 | B8: 중랑구 | D8: 대전광역시 | E8: 순창군
A9: 서울특별시 | B9: 성북구 | D9: 부산광역시 | E9: 완주군
A10: 서울특별시 | B10: 강북구 | D10: 서울특별시 | E10: 익산시
A11: 서울특별시 | B11: 도봉구 | D11: 세종특별자치시 | E11: 임실군
A12: 서울특별시 | B12: 노원구 | D12: 울산광역시 | E12: 장수군
A13: 서울특별시 | B13: 은평구 | D13: 인천광역시 | E13: 전주시
A14: 서울특별시 | B14: 서대문구 | D14: 전라남도 | E14: 정읍시
A15: 서울특별시 | B15: 마포구 | D15: 전라북도 | E15: 진안군
A16: 서울특별시 | B16: 양천구 | D16: 제주특별자치도
A17: 서울특별시 | B17: 강서구 | D17: 충청남도
A18: 서울특별시 | B18: 구로구 | D18: 충청북도
A19: 서울특별시 | B19: 금천구
A20: 서울특별시 | B20: 영등포구
A21: 서울특별시 | B21: 동작구
A22: 서울특별시 | B22: 관악구
A23: 서울특별시 | B23: 서초구
A24: 서울특별시 | B24: 강남구
A25: 서울특별시 | B25: 송파구
A26: 서울특별시 | B26: 강동구
A27: 강원도 | B27: 춘천시
A28: 강원도 | B28: 원주시
A29: 강원도 | B29: 강릉시
A30: 강원도 | B30: 동해시
... A229: 경상남도 | B229: 합천군

Sheet 외기온도_시간분포
A1: 지역별 월별 시간대 외기온도 추정 테이블 (°C) | 방법: T(h) = T월평균 + (DTR/2)×cos(π×(h-14)/12) | 기준: 2025년
A3: ▶ 중부1 (철원) — 월평균기온 및 시간대별 추정온도 (°C)
A4: 시각 (h) | B4: 1월 | C4: 2월 | D4: 3월 | E4: 4월 | F4: 5월 | G4: 6월 | H4: 7월 | I4: 8월 | J4: 9월 | K4: 10월 | L4: 11월 | M4: 12월 | N4: 연평균
A5: 월평균 (°C) | B5: -9.2 | C5: -6.3 | D5: 0.3 | E5: 8.4 | F5: 15 | G5: 19.6 | H5: 24.1 | I5: 24.3 | J5: 17.8 | K5: 9.8 | L5: 1.5 | M5: -6.8 | N5: =AVERAGE(B5,C5,D5,E5,F5,G5,H5,I5,J5,K5,L5,M5) -> 8.2083333
A6: 일교차 (DTR,°C) | B6: 9.8 | C6: 10.2 | D6: 11 | E6: 12.1 | F6: 11.5 | G6: 10 | H6: 8.8 | I6: 9.2 | J6: 10.5 | K6: 11.8 | L6: 10.3 | M6: 9.5 | N6: =AVERAGE(B6,C6,D6,E6,F6,G6,H6,I6,J6,K6,L6,M6) -> 10.391667
A7: 0 | B7: =B5+(B6/2)*-0.866025 -> -13.443523 | C7: =C5+(C6/2)*-0.866025 -> -10.716728 | D7: =D5+(D6/2)*-0.866025 -> -4.4631375 | E7: =E5+(E6/2)*-0.866025 -> 3.1605488 | F7: =F5+(F6/2)*-0.866025 -> 10.020356 | G7: =G5+(G6/2)*-0.866025 -> 15.269875 | H7: =H5+(H6/2)*-0.866025 -> 20.28949 | I7: =I5+(I6/2)*-0.866025 -> 20.316285 | ... M7: =M5+(M6/2)*-0.866025 -> -10.913619 | N7: =AVERAGE(B7,C7,D7,E7,F7,G7,H7,I7,J7,K7,L7,M7) -> 3.7086118
A8: 1 | B8: =B5+(B6/2)*-0.965926 -> -13.933037 | C8: =C5+(C6/2)*-0.965926 -> -11.226223 | D8: =D5+(D6/2)*-0.965926 -> -5.012593 | E8: =E5+(E6/2)*-0.965926 -> 2.5561477 | F8: =F5+(F6/2)*-0.965926 -> 9.4459255 | G8: =G5+(G6/2)*-0.965926 -> 14.77037 | H8: =H5+(H6/2)*-0.965926 -> 19.849926 | I8: =I5+(I6/2)*-0.965926 -> 19.85674 | ... M8: =M5+(M6/2)*-0.965926 -> -11.388148 | N8: =AVERAGE(B8,C8,D8,E8,F8,G8,H8,I8,J8,K8,L8,M8) -> 3.1895428
A9: 2 | B9: =B5+(B6/2)*-1 -> -14.1 | C9: =C5+(C6/2)*-1 -> -11.4 | D9: =D5+(D6/2)*-1 -> -5.2 | E9: =E5+(E6/2)*-1 -> 2.35 | F9: =F5+(F6/2)*-1 -> 9.25 | G9: =G5+(G6/2)*-1 -> 14.6 | H9: =H5+(H6/2)*-1 -> 19.7 | I9: =I5+(I6/2)*-1 -> 19.7 | ... M9: =M5+(M6/2)*-1 -> -11.55 | N9: =AVERAGE(B9,C9,D9,E9,F9,G9,H9,I9,J9,K9,L9,M9) -> 3.0125
A10: 3 | B10: =B5+(B6/2)*-0.965926 -> -13.933037 | C10: =C5+(C6/2)*-0.965926 -> -11.226223 | D10: =D5+(D6/2)*-0.965926 -> -5.012593 | E10: =E5+(E6/2)*-0.965926 -> 2.5561477 | F10: =F5+(F6/2)*-0.965926 -> 9.4459255 | G10: =G5+(G6/2)*-0.965926 -> 14.77037 | H10: =H5+(H6/2)*-0.965926 -> 19.849926 | I10: =I5+(I6/2)*-0.965926 -> 19.85674 | ... M10: =M5+(M6/2)*-0.965926 -> -11.388148 | N10: =AVERAGE(B10,C10,D10,E10,F10,G10,H10,I10,J10,K10,L10,M10) -> 3.1895428
A11: 4 | B11: =B5+(B6/2)*-0.866025 -> -13.443523 | C11: =C5+(C6/2)*-0.866025 -> -10.716728 | D11: =D5+(D6/2)*-0.866025 -> -4.4631375 | E11: =E5+(E6/2)*-0.866025 -> 3.1605488 | F11: =F5+(F6/2)*-0.866025 -> 10.020356 | G11: =G5+(G6/2)*-0.866025 -> 15.269875 | H11: =H5+(H6/2)*-0.866025 -> 20.28949 | I11: =I5+(I6/2)*-0.866025 -> 20.316285 | ... M11: =M5+(M6/2)*-0.866025 -> -10.913619 | N11: =AVERAGE(B11,C11,D11,E11,F11,G11,H11,I11,J11,K11,L11,M11) -> 3.7086118
A12: 5 | B12: =B5+(B6/2)*-0.707107 -> -12.664824 | C12: =C5+(C6/2)*-0.707107 -> -9.9062457 | D12: =D5+(D6/2)*-0.707107 -> -3.5890885 | E12: =E5+(E6/2)*-0.707107 -> 4.1220027 | F12: =F5+(F6/2)*-0.707107 -> 10.934135 | G12: =G5+(G6/2)*-0.707107 -> 16.064465 | H12: =H5+(H6/2)*-0.707107 -> 20.988729 | I12: =I5+(I6/2)*-0.707107 -> 21.047308 | ... M12: =M5+(M6/2)*-0.707107 -> -10.158758 | N12: =AVERAGE(B12,C12,D12,E12,F12,G12,H12,I12,J12,K12,L12,M12) -> 4.5343232
A13: 6 | B13: =B5+(B6/2)*-0.5 -> -11.65 | C13: =C5+(C6/2)*-0.5 -> -8.85 | D13: =D5+(D6/2)*-0.5 -> -2.45 | E13: =E5+(E6/2)*-0.5 -> 5.375 | F13: =F5+(F6/2)*-0.5 -> 12.125 | G13: =G5+(G6/2)*-0.5 -> 17.1 | H13: =H5+(H6/2)*-0.5 -> 21.9 | I13: =I5+(I6/2)*-0.5 -> 22 | ... M13: =M5+(M6/2)*-0.5 -> -9.175 | N13: =AVERAGE(B13,C13,D13,E13,F13,G13,H13,I13,J13,K13,L13,M13) -> 5.6104167
A14: 7 | B14: =B5+(B6/2)*-0.258819 -> -10.468213 | C14: =C5+(C6/2)*-0.258819 -> -7.6199769 | D14: =D5+(D6/2)*-0.258819 -> -1.1235045 | E14: =E5+(E6/2)*-0.258819 -> 6.8341451 | F14: =F5+(F6/2)*-0.258819 -> 13.511791 | G14: =G5+(G6/2)*-0.258819 -> 18.305905 | H14: =H5+(H6/2)*-0.258819 -> 22.961196 | I14: =I5+(I6/2)*-0.258819 -> 23.109433 | ... M14: =M5+(M6/2)*-0.258819 -> -8.0293903 | N14: =AVERAGE(B14,C14,D14,E14,F14,G14,H14,I14,J14,K14,L14,M14) -> 6.8635529
A15: 8 | B15: =B5+(B6/2)*0 -> -9.2 | C15: =C5+(C6/2)*0 -> -6.3 | D15: =D5+(D6/2)*0 -> 0.3 | E15: =E5+(E6/2)*0 -> 8.4 | F15: =F5+(F6/2)*0 -> 15 | G15: =G5+(G6/2)*0 -> 19.6 | H15: =H5+(H6/2)*0 -> 24.1 | I15: =I5+(I6/2)*0 -> 24.3 | ... M15: =M5+(M6/2)*0 -> -6.8 | N15: =AVERAGE(B15,C15,D15,E15,F15,G15,H15,I15,J15,K15,L15,M15) -> 8.2083333
A16: 9 | B16: =B5+(B6/2)*0.258819 -> -7.9317869 | C16: =C5+(C6/2)*0.258819 -> -4.9800231 | D16: =D5+(D6/2)*0.258819 -> 1.7235045 | E16: =E5+(E6/2)*0.258819 -> 9.965855 | F16: =F5+(F6/2)*0.258819 -> 16.488209 | G16: =G5+(G6/2)*0.258819 -> 20.894095 | H16: =H5+(H6/2)*0.258819 -> 25.238804 | I16: =I5+(I6/2)*0.258819 -> 25.490567 | ... M16: =M5+(M6/2)*0.258819 -> -5.5706098 | N16: =AVERAGE(B16,C16,D16,E16,F16,G16,H16,I16,J16,K16,L16,M16) -> 9.5531137
A17: 10 | B17: =B5+(B6/2)*0.5 -> -6.75 | C17: =C5+(C6/2)*0.5 -> -3.75 | D17: =D5+(D6/2)*0.5 -> 3.05 | E17: =E5+(E6/2)*0.5 -> 11.425 | F17: =F5+(F6/2)*0.5 -> 17.875 | G17: =G5+(G6/2)*0.5 -> 22.1 | H17: =H5+(H6/2)*0.5 -> 26.3 | I17: =I5+(I6/2)*0.5 -> 26.6 | ... M17: =M5+(M6/2)*0.5 -> -4.425 | N17: =AVERAGE(B17,C17,D17,E17,F17,G17,H17,I17,J17,K17,L17,M17) -> 10.80625
A18: 11 | B18: =B5+(B6/2)*0.707107 -> -5.7351757 | C18: =C5+(C6/2)*0.707107 -> -2.6937543 | D18: =D5+(D6/2)*0.707107 -> 4.1890885 | E18: =E5+(E6/2)*0.707107 -> 12.677997 | F18: =F5+(F6/2)*0.707107 -> 19.065865 | G18: =G5+(G6/2)*0.707107 -> 23.135535 | H18: =H5+(H6/2)*0.707107 -> 27.211271 | I18: =I5+(I6/2)*0.707107 -> 27.552692 | ... M18: =M5+(M6/2)*0.707107 -> -3.4412417 | N18: =AVERAGE(B18,C18,D18,E18,F18,G18,H18,I18,J18,K18,L18,M18) -> 11.882343
A19: 12 | B19: =B5+(B6/2)*0.866025 -> -4.9564775 | C19: =C5+(C6/2)*0.866025 -> -1.8832725 | D19: =D5+(D6/2)*0.866025 -> 5.0631375 | E19: =E5+(E6/2)*0.866025 -> 13.639451 | F19: =F5+(F6/2)*0.866025 -> 19.979644 | G19: =G5+(G6/2)*0.866025 -> 23.930125 | H19: =H5+(H6/2)*0.866025 -> 27.91051 | I19: =I5+(I6/2)*0.866025 -> 28.283715 | ... M19: =M5+(M6/2)*0.866025 -> -2.6863812 | N19: =AVERAGE(B19,C19,D19,E19,F19,G19,H19,I19,J19,K19,L19,M19) -> 12.708055
A20: 13 | B20: =B5+(B6/2)*0.965926 -> -4.4669626 | C20: =C5+(C6/2)*0.965926 -> -1.3737774 | D20: =D5+(D6/2)*0.965926 -> 5.612593 | E20: =E5+(E6/2)*0.965926 -> 14.243852 | F20: =F5+(F6/2)*0.965926 -> 20.554074 | G20: =G5+(G6/2)*0.965926 -> 24.42963 | H20: =H5+(H6/2)*0.965926 -> 28.350074 | I20: =I5+(I6/2)*0.965926 -> 28.74326 | ... M20: =M5+(M6/2)*0.965926 -> -2.2118515 | N20: =AVERAGE(B20,C20,D20,E20,F20,G20,H20,I20,J20,K20,L20,M20) -> 13.227124
A21: 14 | B21: =B5+(B6/2)*1 -> -4.3 | C21: =C5+(C6/2)*1 -> -1.2 | D21: =D5+(D6/2)*1 -> 5.8 | E21: =E5+(E6/2)*1 -> 14.45 | F21: =F5+(F6/2)*1 -> 20.75 | G21: =G5+(G6/2)*1 -> 24.6 | H21: =H5+(H6/2)*1 -> 28.5 | I21: =I5+(I6/2)*1 -> 28.9 | ... M21: =M5+(M6/2)*1 -> -2.05 | N21: =AVERAGE(B21,C21,D21,E21,F21,G21,H21,I21,J21,K21,L21,M21) -> 13.404167
A22: 15 | B22: =B5+(B6/2)*0.965926 -> -4.4669626 | C22: =C5+(C6/2)*0.965926 -> -1.3737774 | D22: =D5+(D6/2)*0.965926 -> 5.612593 | E22: =E5+(E6/2)*0.965926 -> 14.243852 | F22: =F5+(F6/2)*0.965926 -> 20.554074 | G22: =G5+(G6/2)*0.965926 -> 24.42963 | H22: =H5+(H6/2)*0.965926 -> 28.350074 | I22: =I5+(I6/2)*0.965926 -> 28.74326 | ... M22: =M5+(M6/2)*0.965926 -> -2.2118515 | N22: =AVERAGE(B22,C22,D22,E22,F22,G22,H22,I22,J22,K22,L22,M22) -> 13.227124
A23: 16 | B23: =B5+(B6/2)*0.866025 -> -4.9564775 | C23: =C5+(C6/2)*0.866025 -> -1.8832725 | D23: =D5+(D6/2)*0.866025 -> 5.0631375 | E23: =E5+(E6/2)*0.866025 -> 13.639451 | F23: =F5+(F6/2)*0.866025 -> 19.979644 | G23: =G5+(G6/2)*0.866025 -> 23.930125 | H23: =H5+(H6/2)*0.866025 -> 27.91051 | I23: =I5+(I6/2)*0.866025 -> 28.283715 | ... M23: =M5+(M6/2)*0.866025 -> -2.6863812 | N23: =AVERAGE(B23,C23,D23,E23,F23,G23,H23,I23,J23,K23,L23,M23) -> 12.708055
A24: 17 | B24: =B5+(B6/2)*0.707107 -> -5.7351757 | C24: =C5+(C6/2)*0.707107 -> -2.6937543 | D24: =D5+(D6/2)*0.707107 -> 4.1890885 | E24: =E5+(E6/2)*0.707107 -> 12.677997 | F24: =F5+(F6/2)*0.707107 -> 19.065865 | G24: =G5+(G6/2)*0.707107 -> 23.135535 | H24: =H5+(H6/2)*0.707107 -> 27.211271 | I24: =I5+(I6/2)*0.707107 -> 27.552692 | ... M24: =M5+(M6/2)*0.707107 -> -3.4412417 | N24: =AVERAGE(B24,C24,D24,E24,F24,G24,H24,I24,J24,K24,L24,M24) -> 11.882343
A25: 18 | B25: =B5+(B6/2)*0.5 -> -6.75 | C25: =C5+(C6/2)*0.5 -> -3.75 | D25: =D5+(D6/2)*0.5 -> 3.05 | E25: =E5+(E6/2)*0.5 -> 11.425 | F25: =F5+(F6/2)*0.5 -> 17.875 | G25: =G5+(G6/2)*0.5 -> 22.1 | H25: =H5+(H6/2)*0.5 -> 26.3 | I25: =I5+(I6/2)*0.5 -> 26.6 | ... M25: =M5+(M6/2)*0.5 -> -4.425 | N25: =AVERAGE(B25,C25,D25,E25,F25,G25,H25,I25,J25,K25,L25,M25) -> 10.80625
A26: 19 | B26: =B5+(B6/2)*0.258819 -> -7.9317869 | C26: =C5+(C6/2)*0.258819 -> -4.9800231 | D26: =D5+(D6/2)*0.258819 -> 1.7235045 | E26: =E5+(E6/2)*0.258819 -> 9.965855 | F26: =F5+(F6/2)*0.258819 -> 16.488209 | G26: =G5+(G6/2)*0.258819 -> 20.894095 | H26: =H5+(H6/2)*0.258819 -> 25.238804 | I26: =I5+(I6/2)*0.258819 -> 25.490567 | ... M26: =M5+(M6/2)*0.258819 -> -5.5706098 | N26: =AVERAGE(B26,C26,D26,E26,F26,G26,H26,I26,J26,K26,L26,M26) -> 9.5531137
A27: 20 | B27: =B5+(B6/2)*0 -> -9.2 | C27: =C5+(C6/2)*0 -> -6.3 | D27: =D5+(D6/2)*0 -> 0.3 | E27: =E5+(E6/2)*0 -> 8.4 | F27: =F5+(F6/2)*0 -> 15 | G27: =G5+(G6/2)*0 -> 19.6 | H27: =H5+(H6/2)*0 -> 24.1 | I27: =I5+(I6/2)*0 -> 24.3 | ... M27: =M5+(M6/2)*0 -> -6.8 | N27: =AVERAGE(B27,C27,D27,E27,F27,G27,H27,I27,J27,K27,L27,M27) -> 8.2083333
A28: 21 | B28: =B5+(B6/2)*-0.258819 -> -10.468213 | C28: =C5+(C6/2)*-0.258819 -> -7.6199769 | D28: =D5+(D6/2)*-0.258819 -> -1.1235045 | E28: =E5+(E6/2)*-0.258819 -> 6.8341451 | F28: =F5+(F6/2)*-0.258819 -> 13.511791 | G28: =G5+(G6/2)*-0.258819 -> 18.305905 | H28: =H5+(H6/2)*-0.258819 -> 22.961196 | I28: =I5+(I6/2)*-0.258819 -> 23.109433 | ... M28: =M5+(M6/2)*-0.258819 -> -8.0293903 | N28: =AVERAGE(B28,C28,D28,E28,F28,G28,H28,I28,J28,K28,L28,M28) -> 6.8635529
A29: 22 | B29: =B5+(B6/2)*-0.5 -> -11.65 | C29: =C5+(C6/2)*-0.5 -> -8.85 | D29: =D5+(D6/2)*-0.5 -> -2.45 | E29: =E5+(E6/2)*-0.5 -> 5.375 | F29: =F5+(F6/2)*-0.5 -> 12.125 | G29: =G5+(G6/2)*-0.5 -> 17.1 | H29: =H5+(H6/2)*-0.5 -> 21.9 | I29: =I5+(I6/2)*-0.5 -> 22 | ... M29: =M5+(M6/2)*-0.5 -> -9.175 | N29: =AVERAGE(B29,C29,D29,E29,F29,G29,H29,I29,J29,K29,L29,M29) -> 5.6104167
A30: ▶ 중부2 (서울) — 월평균기온 및 시간대별 추정온도 (°C)
A31: 시각 (h) | B31: 1월 | C31: 2월 | D31: 3월 | E31: 4월 | F31: 5월 | G31: 6월 | H31: 7월 | I31: 8월 | J31: 9월 | K31: 10월 | L31: 11월 | M31: 12월 | N31: 연평균
A32: 월평균 (°C) | B32: -1.8 | C32: 0.8 | D32: 6.5 | E32: 13.2 | F32: 18.5 | G32: 23 | H32: 26.4 | I32: 27.1 | J32: 22 | K32: 15.2 | L32: 7.5 | M32: 0.5 | N32: =AVERAGE(B32,C32,D32,E32,F32,G32,H32,I32,J32,K32,L32,M32) -> 13.241667
A33: 일교차 (DTR,°C) | B33: 7.2 | C33: 8 | D33: 9.5 | E33: 10.8 | F33: 9.8 | G33: 8.5 | H33: 7.5 | I33: 7.8 | J33: 8.8 | K33: 10.2 | L33: 9 | M33: 7.5 | N33: =AVERAGE(B33,C33,D33,E33,F33,G33,H33,I33,J33,K33,L33,M33) -> 8.7166667
A34: 0 | B34: =B32+(B33/2)*-0.866025 -> -4.91769 | C34: =C32+(C33/2)*-0.866025 -> -2.6641 | D34: =D32+(D33/2)*-0.866025 -> 2.3863812 | E34: =E32+(E33/2)*-0.866025 -> 8.523465 | F34: =F32+(F33/2)*-0.866025 -> 14.256477 | G34: =G32+(G33/2)*-0.866025 -> 19.319394 | H34: =H32+(H33/2)*-0.866025 -> 23.152406 | I34: =I32+(I33/2)*-0.866025 -> 23.722503 | ... M34: =M32+(M33/2)*-0.866025 -> -2.7475938 | N34: =AVERAGE(B34,C34,D34,E34,F34,G34,H34,I34,J34,K34,L34,M34) -> 9.467241
A35: 1 | B35: =B32+(B33/2)*-0.965926 -> -5.2773336 | C35: =C32+(C33/2)*-0.965926 -> -3.063704 | D35: =D32+(D33/2)*-0.965926 -> 1.9118515 | E35: =E32+(E33/2)*-0.965926 -> 7.9839996 | F35: =F32+(F33/2)*-0.965926 -> 13.766963 | G35: =G32+(G33/2)*-0.965926 -> 18.894814 | H35: =H32+(H33/2)*-0.965926 -> 22.777777 | I35: =I32+(I33/2)*-0.965926 -> 23.332889 | ... M35: =M32+(M33/2)*-0.965926 -> -3.1222225 | N35: =AVERAGE(B35,C35,D35,E35,F35,G35,H35,I35,J35,K35,L35,M35) -> 9.0318392
A36: 2 | B36: =B32+(B33/2)*-1 -> -5.4 | C36: =C32+(C33/2)*-1 -> -3.2 | D36: =D32+(D33/2)*-1 -> 1.75 | E36: =E32+(E33/2)*-1 -> 7.8 | F36: =F32+(F33/2)*-1 -> 13.6 | G36: =G32+(G33/2)*-1 -> 18.75 | H36: =H32+(H33/2)*-1 -> 22.65 | I36: =I32+(I33/2)*-1 -> 23.2 | ... M36: =M32+(M33/2)*-1 -> -3.25 | N36: =AVERAGE(B36,C36,D36,E36,F36,G36,H36,I36,J36,K36,L36,M36) -> 8.8833333
A37: 3 | B37: =B32+(B33/2)*-0.965926 -> -5.2773336 | C37: =C32+(C33/2)*-0.965926 -> -3.063704 | D37: =D32+(D33/2)*-0.965926 -> 1.9118515 | E37: =E32+(E33/2)*-0.965926 -> 7.9839996 | F37: =F32+(F33/2)*-0.965926 -> 13.766963 | G37: =G32+(G33/2)*-0.965926 -> 18.894814 | H37: =H32+(H33/2)*-0.965926 -> 22.777777 | I37: =I32+(I33/2)*-0.965926 -> 23.332889 | ... M37: =M32+(M33/2)*-0.965926 -> -3.1222225 | N37: =AVERAGE(B37,C37,D37,E37,F37,G37,H37,I37,J37,K37,L37,M37) -> 9.0318392
A38: 4 | B38: =B32+(B33/2)*-0.866025 -> -4.91769 | C38: =C32+(C33/2)*-0.866025 -> -2.6641 | D38: =D32+(D33/2)*-0.866025 -> 2.3863812 | E38: =E32+(E33/2)*-0.866025 -> 8.523465 | F38: =F32+(F33/2)*-0.866025 -> 14.256477 | G38: =G32+(G33/2)*-0.866025 -> 19.319394 | H38: =H32+(H33/2)*-0.866025 -> 23.152406 | I38: =I32+(I33/2)*-0.866025 -> 23.722503 | ... M38: =M32+(M33/2)*-0.866025 -> -2.7475938 | N38: =AVERAGE(B38,C38,D38,E38,F38,G38,H38,I38,J38,K38,L38,M38) -> 9.467241
A39: 5 | B39: =B32+(B33/2)*-0.707107 -> -4.3455852 | C39: =C32+(C33/2)*-0.707107 -> -2.028428 | D39: =D32+(D33/2)*-0.707107 -> 3.1412417 | E39: =E32+(E33/2)*-0.707107 -> 9.3816222 | F39: =F32+(F33/2)*-0.707107 -> 15.035176 | G39: =G32+(G33/2)*-0.707107 -> 19.994795 | H39: =H32+(H33/2)*-0.707107 -> 23.748349 | I39: =I32+(I33/2)*-0.707107 -> 24.342283 | ... M39: =M32+(M33/2)*-0.707107 -> -2.1516513 | N39: =AVERAGE(B39,C39,D39,E39,F39,G39,H39,I39,J39,K39,L39,M39) -> 10.159859
A40: 6 | B40: =B32+(B33/2)*-0.5 -> -3.6 | C40: =C32+(C33/2)*-0.5 -> -1.2 | D40: =D32+(D33/2)*-0.5 -> 4.125 | E40: =E32+(E33/2)*-0.5 -> 10.5 | F40: =F32+(F33/2)*-0.5 -> 16.05 | G40: =G32+(G33/2)*-0.5 -> 20.875 | H40: =H32+(H33/2)*-0.5 -> 24.525 | I40: =I32+(I33/2)*-0.5 -> 25.15 | ... M40: =M32+(M33/2)*-0.5 -> -1.375 | N40: =AVERAGE(B40,C40,D40,E40,F40,G40,H40,I40,J40,K40,L40,M40) -> 11.0625
A41: 7 | B41: =B32+(B33/2)*-0.258819 -> -2.7317484 | C41: =C32+(C33/2)*-0.258819 -> -0.235276 | D41: =D32+(D33/2)*-0.258819 -> 5.2706098 | E41: =E32+(E33/2)*-0.258819 -> 11.802377 | F41: =F32+(F33/2)*-0.258819 -> 17.231787 | G41: =G32+(G33/2)*-0.258819 -> 21.900019 | H41: =H32+(H33/2)*-0.258819 -> 25.429429 | I41: =I32+(I33/2)*-0.258819 -> 26.090606 | ... M41: =M32+(M33/2)*-0.258819 -> -0.47057125 | N41: =AVERAGE(B41,C41,D41,E41,F41,G41,H41,I41,J41,K41,L41,M41) -> 12.113647
...

Sheet COP_계산기
A1: 히트펌프 난방 COP 계산기 | 시간별 온도 → 난방수요 가중평균 sCOP 자동 계산
A3: ▶ 입력 파라미터 (파란 글씨 셀만 수정)
A4: 공급수 온도 Ts (°C) | D4: 55 | E4: ← 바닥난방 35~45 / 라디에이터 55~70
A5: 카르노 보정계수 η | D5: 0.45 | E5: ← 실제/이론 효율비. 일반 범위: 0.4~0.6
A6: 난방 기준온도 Tbase (°C) | D6: 18 | E6: ← HDD 계산 기준. 국내 표준: 15°C 또는 18°C
A7: 목표 sCOP | D7: 3 | E7: ← 달성 목표값 (비교용)
A9: ※ 계산식: COP(월,h) = η × (Ts+273) / max(1, Ts−T(월,h)) │ 월평균COP = 난방시간 가중평균 (T < Tbase 시간만 포함) │ sCOP = Σ(월난방수요×월COP) / Σ(월난방수요) │ T 데이터 출처: '외기온도_시간분포' 시트
A11: 지역 | B11: 항목 | C11: 1월 | D11: 2월 | E11: 3월 | F11: 4월 | G11: 5월 | H11: 6월 | I11: 7월 | J11: 8월 | K11: 9월 | L11: 10월 | M11: 11월 | N11: 12월 | O11: 연간 합계/평균 | P11: sCOP (HDD가중) | Q11: 목표 sCOP | R11: 달성 여부
A12: 중부1 | B12: 월평균기온(°C) | C12: =외기온도_시간분포!B5 -> -9.2 | D12: =외기온도_시간분포!C5 -> -6.3 | E12: =외기온도_시간분포!D5 -> 0.3 | F12: =외기온도_시간분포!E5 -> 8.4 | G12: =외기온도_시간분포!F5 -> 15 | H12: =외기온도_시간분포!G5 -> 19.6 | I12: =외기온도_시간분포!H5 -> 24.1 | J12: =외기온도_시간분포!I5 -> 24.3 | ... N12: =외기온도_시간분포!M5 -> -6.8 | O12: =AVERAGE(C12:N12) -> 8.2083333 | P12: =IFERROR(SUMPRODUCT(C13:N13,C14:N14)/SUM(C13:N13),0) -> 2.6069253 | Q12: =$D$7 -> 3 | R12: =IF(P12>=$D$7,"✓ 달성","✗ 미달") -> ✗ 미달
B13: 월 HDD (난방도일) | C13: =MAX(0,$D$6-C12)*31 -> 843.2 | D13: =MAX(0,$D$6-D12)*28 -> 680.4 | E13: =MAX(0,$D$6-E12)*31 -> 548.7 | F13: =MAX(0,$D$6-F12)*30 -> 288 | G13: =MAX(0,$D$6-G12)*31 -> 93 | H13: =MAX(0,$D$6-H12)*30 -> 0 | I13: =MAX(0,$D$6-I12)*31 -> 0 | J13: =MAX(0,$D$6-J12)*31 -> 0 | K13: =MAX(0,$D$6-K12)*30 -> 6 | L13: =MAX(0,$D$6-L12)*31 -> 254.2 | M13: =MAX(0,$D$6-M12)*30 -> 495 | N13: =MAX(0,$D$6-N12)*31 -> 768.8 | O13: =SUM(C13:N13) -> 3977.3
B14: 월 COP (난방시간 가중) | C14: =$D$5*($D$4+273)/MAX(1,$D$4-C12) -> 2.2990654 | D14: =$D$5*($D$4+273)/MAX(1,$D$4-D12) -> 2.4078303 | E14: =$D$5*($D$4+273)/MAX(1,$D$4-E12) -> 2.6983547 | F14: =$D$5*($D$4+273)/MAX(1,$D$4-F12) -> 3.167382 | G14: =$D$5*($D$4+273)/MAX(1,$D$4-G12) -> 3.69 | H14: =$D$5*($D$4+273)/MAX(1,$D$4-H12) -> 4.1694915 | I14: =$D$5*($D$4+273)/MAX(1,$D$4-I12) -> 4.776699 | J14: =$D$5*($D$4+273)/MAX(1,$D$4-J12) -> 4.8078176 | ... N14: =$D$5*($D$4+273)/MAX(1,$D$4-N12) -> 2.3883495 | O14: =AVERAGE(C14:N14) -> 3.3664248
A16: 중부2 | B16: 월평균기온(°C) | C16: =외기온도_시간분포!B32 -> -1.8 | D16: =외기온도_시간분포!C32 -> 0.8 | E16: =외기온도_시간분포!D32 -> 6.5 | F16: =외기온도_시간분포!E32 -> 13.2 | G16: =외기온도_시간분포!F32 -> 18.5 | H16: =외기온도_시간분포!G32 -> 23 | I16: =외기온도_시간분포!H32 -> 26.4 | J16: =외기온도_시간분포!I32 -> 27.1 | ... N16: =외기온도_시간분포!M32 -> 0.5 | O16: =AVERAGE(C16:N16) -> 13.241667 | P16: =IFERROR(SUMPRODUCT(C17:N17,C18:N18)/SUM(C17:N17),0) -> 2.8619392 | Q16: =$D$7 -> 3 | R16: =IF(P16>=$D$7,"✓ 달성","✗ 미달") -> ✗ 미달
B17: 월 HDD (난방도일) | C17: =MAX(0,$D$6-C16)*31 -> 613.8 | D17: =MAX(0,$D$6-D16)*28 -> 481.6 | E17: =MAX(0,$D$6-E16)*31 -> 356.5 | F17: =MAX(0,$D$6-F16)*30 -> 144 | G17: =MAX(0,$D$6-G16)*31 -> 0 | H17: =MAX(0,$D$6-H16)*30 -> 0 | I17: =MAX(0,$D$6-I16)*31 -> 0 | J17: =MAX(0,$D$6-J16)*31 -> 0 | K17: =MAX(0,$D$6-K16)*30 -> 0 | L17: =MAX(0,$D$6-L16)*31 -> 86.8 | M17: =MAX(0,$D$6-M16)*30 -> 315 | N17: =MAX(0,$D$6-N16)*31 -> 542.5 | O17: =SUM(C17:N17) -> 2540.2
B18: 월 COP (난방시간 가중) | C18: =$D$5*($D$4+273)/MAX(1,$D$4-C16) -> 2.5985915 | D18: =$D$5*($D$4+273)/MAX(1,$D$4-D16) -> 2.7232472 | E18: =$D$5*($D$4+273)/MAX(1,$D$4-E16) -> 3.043299 | F18: =$D$5*($D$4+273)/MAX(1,$D$4-F16) -> 3.5311005 | G18: =$D$5*($D$4+273)/MAX(1,$D$4-G16) -> 4.0438356 | H18: =$D$5*($D$4+273)/MAX(1,$D$4-H16) -> 4.6125 | I18: =$D$5*($D$4+273)/MAX(1,$D$4-I16) -> 5.1608392 | J18: =$D$5*($D$4+273)/MAX(1,$D$4-J16) -> 5.2903226 | ... N18: =$D$5*($D$4+273)/MAX(1,$D$4-N16) -> 2.7082569 | O18: =AVERAGE(C18:N18) -> 3.7500526
A20: 남부 | B20: 월평균기온(°C) | C20: =외기온도_시간분포!B59 -> 3.8 | D20: =외기온도_시간분포!C59 -> 5.4 | E20: =외기온도_시간분포!D59 -> 9.5 | F20: =외기온도_시간분포!E59 -> 15.2 | G20: =외기온도_시간분포!F59 -> 19.5 | H20: =외기온도_시간분포!G59 -> 22.5 | I20: =외기온도_시간분포!H59 -> 26 | J20: =외기온도_시간분포!I59 -> 27.2 | ... N20: =외기온도_시간분포!M59 -> 5.5 | O20: =AVERAGE(C20:N20) -> 15.541667 | P20: =IFERROR(SUMPRODUCT(C21:N21,C22:N22)/SUM(C21:N21),0) -> 3.0838874 | Q20: =$D$7 -> 3 | R20: =IF(P20>=$D$7,"✓ 달성","✗ 미달") -> ✓ 달성
B21: 월 HDD (난방도일) | C21: =MAX(0,$D$6-C20)*31 -> 440.2 | D21: =MAX(0,$D$6-D20)*28 -> 352.8 | E21: =MAX(0,$D$6-E20)*31 -> 263.5 | F21: =MAX(0,$D$6-F20)*30 -> 84 | G21: =MAX(0,$D$6-G20)*31 -> 0 | H21: =MAX(0,$D$6-H20)*30 -> 0 | I21: =MAX(0,$D$6-I20)*31 -> 0 | J21: =MAX(0,$D$6-J20)*31 -> 0 | K21: =MAX(0,$D$6-K20)*30 -> 0 | L21: =MAX(0,$D$6-L20)*31 -> 15.5 | M21: =MAX(0,$D$6-M20)*30 -> 204 | N21: =MAX(0,$D$6-N20)*31 -> 387.5 | O21: =SUM(C21:N21) -> 1747.5
B22: 월 COP (난방시간 가중) | C22: =$D$5*($D$4+273)/MAX(1,$D$4-C20) -> 2.8828125 | D22: =$D$5*($D$4+273)/MAX(1,$D$4-D20) -> 2.9758065 | E22: =$D$5*($D$4+273)/MAX(1,$D$4-E20) -> 3.243956 | F22: =$D$5*($D$4+273)/MAX(1,$D$4-F20) -> 3.7085427 | G22: =$D$5*($D$4+273)/MAX(1,$D$4-G20) -> 4.1577465 | H22: =$D$5*($D$4+273)/MAX(1,$D$4-H20) -> 4.5415385 | I22: =$D$5*($D$4+273)/MAX(1,$D$4-I20) -> 5.0896552 | J22: =$D$5*($D$4+273)/MAX(1,$D$4-J20) -> 5.3093525 | ... N22: =$D$5*($D$4+273)/MAX(1,$D$4-N20) -> 2.9818182 | O22: =AVERAGE(C22:N22) -> 3.9032167
A24: 제주 | B24: 월평균기온(°C) | C24: =외기온도_시간분포!B86 -> 6.2 | D24: =외기온도_시간분포!C86 -> 7 | E24: =외기온도_시간분포!D86 -> 10.5 | F24: =외기온도_시간분포!E86 -> 15.2 | G24: =외기온도_시간분포!F86 -> 19.5 | H24: =외기온도_시간분포!G86 -> 23 | I24: =외기온도_시간분포!H86 -> 27.2 | J24: =외기온도_시간분포!I86 -> 28 | ... N24: =외기온도_시간분포!M86 -> 8.2 | O24: =AVERAGE(C24:N24) -> 16.775 | P24: =IFERROR(SUMPRODUCT(C25:N25,C26:N26)/SUM(C25:N25),0) -> 3.2009406 | Q24: =$D$7 -> 3 | R24: =IF(P24>=$D$7,"✓ 달성","✗ 미달") -> ✓ 달성
B25: 월 HDD (난방도일) | C25: =MAX(0,$D$6-C24)*31 -> 365.8 | D25: =MAX(0,$D$6-D24)*28 -> 308 | E25: =MAX(0,$D$6-E24)*31 -> 232.5 | F25: =MAX(0,$D$6-F24)*30 -> 84 | G25: =MAX(0,$D$6-G24)*31 -> 0 | H25: =MAX(0,$D$6-H24)*30 -> 0 | I25: =MAX(0,$D$6-I24)*31 -> 0 | J25: =MAX(0,$D$6-J24)*31 -> 0 | K25: =MAX(0,$D$6-K24)*30 -> 0 | L25: =MAX(0,$D$6-L24)*31 -> 0 | M25: =MAX(0,$D$6-M24)*30 -> 135 | N25: =MAX(0,$D$6-N24)*31 -> 303.8 | O25: =SUM(C25:N25) -> 1429.1
B26: 월 COP (난방시간 가중) | C26: =$D$5*($D$4+273)/MAX(1,$D$4-C24) -> 3.0245902 | D26: =$D$5*($D$4+273)/MAX(1,$D$4-D24) -> 3.075 | E26: =$D$5*($D$4+273)/MAX(1,$D$4-E24) -> 3.3168539 | F26: =$D$5*($D$4+273)/MAX(1,$D$4-F24) -> 3.7085427 | G26: =$D$5*($D$4+273)/MAX(1,$D$4-G24) -> 4.1577465 | H26: =$D$5*($D$4+273)/MAX(1,$D$4-H24) -> 4.6125 | I26: =$D$5*($D$4+273)/MAX(1,$D$4-I24) -> 5.3093525 | J26: =$D$5*($D$4+273)/MAX(1,$D$4-J24) -> 5.4666667 | ... N26: =$D$5*($D$4+273)/MAX(1,$D$4-N24) -> 3.1538462 | O26: =AVERAGE(C26:N26) -> 4.0202513

Sheet 전기요금
AK3: 최종 파일(월별 1kW당 발전량)(단위: kWh)
C4: 주택용 저압 기타계절 | S4: HP전기요금 연합계 | T4: 기존난방비 연합계 | U4: 난방비 Saving 비율 | AK4: 광역지자체 | AM4: 1월 | AN4: 2월 | AO4: 3월 | AP4: 4월 | AQ4: 5월 | AR4: 6월 | AS4: 7월 | AT4: 8월 | AU4: 9월 | AV4: 10월 | AW4: 11월 | AX4: 12월 | AZ4: 가전만 청구합계(차감기준)
B5: 기본요금(원/호) | D5: 전력량요금(원/kWh) | H5: 누진제 태X | I5: 도시가스(컨덴싱)->HP | J5: 기본요금 | K5: 사용량요금 | L5: 기후환경요금 | M5: 연료비조정요금 | N5: 전기요금계 | O5: 부가가치세 | P5: 전력산업기반기금 | Q5: 청구요금합계 | R5: HP전기요금 | S5: =SUM(R6:R17) -> 3483280 | T5: =Sheet2!O18 -> 1620551.6 | U5: =(T5-S5)/T5 -> -1.1494409 | AK5: 서울특별시 | AM5: 53.059104 | AN5: 79.802604 | AO5: 92.616561 | AP5: 104.98734 | AQ5: 98.064594 | AR5: 96.96429 | AS5: 95.222142 | AT5: 72.719397 | AU5: 56.61981 | AV5: 67.745106 | AW5: 65.55978 | AX5: 49.979781 | BA5: 월 | BB5: 누진_태X | BC5: 누진_태O | BD5: 계시_태X | BE5: 계시_태O
B6: 200kWh이하 사용 | C6: 910 | D6: 처음 200kWh까지 | E6: 120 | I6: 1 | J6: =IF((Sheet2!C54+C23)<=200, 910, IF((Sheet2!C54+C23)<=400, 1600, 7300)) -> 7300 | K6: =INT(IF((Sheet2!C54+C23)<=200, (Sheet2!C54+C23)*120, IF((Sheet2!C54+C23)<=400, 24000+((Sheet2!C54+C23)-200)*214.6, 66920+((Sheet2!C54+C23)-400)*307.3)))+INT(MAX((Sheet2!C54+C23)-1000,0)*(736.2-307.3)) -> 1493421 | L6: =INT((Sheet2!C54+C23)*9) -> 24184 | M6: =INT((Sheet2!C54+C23)*5) -> 13436 | N6: =SUM(J6:M6) -> 1538341 | O6: =ROUND(N6*0.1, 0) -> 153834 | P6: =FLOOR(N6*0.027, 10) -> 41530 | Q6: =FLOOR(N6+O6+P6, 10) -> 1733700 | R6: =MAX(Q6-BB6,0) -> 1003750 | AK6: 인천광역시 | AM6: 53.059104 | AN6: 79.802604 | AO6: 92.616561 | AP6: 104.98734 | AQ6: 98.064594 | AR6: 96.96429 | AS6: 95.222142 | AT6: 72.719397 | AU6: 56.61981 | AV6: 67.745106 | AW6: 65.55978 | AX6: 49.979781 | BA6: 1 | BB6: =FLOOR(((IF((0+C23)<=200, 910, IF((0+C23)<=400, 1600, 7300)))+(INT(IF((0+C23)<=200, (0+C23)*120, IF((0+C23)<=400, 24000+((0+C23)-200)*214.6, 66920+((0+C23)-400)*307.3)))+INT(MAX((0+C23)-1000,0)*(736.2-307.3)))+(INT((0+C23)*9))+(INT((0+C23)*5)))+ROUND(((IF((0+C23)<=200, 910, IF((0+C23)<=400, 1600, 7300)))+(INT(IF((0+C23)<=200, (0+C23)*120, IF((0+C23)<=400, 24000+((0+C23)-200)*214.6, 66920+((0+C23)-400)*307.3)))+INT(MAX((0+C23)-1000,0)*(736.2-307.3)))+(INT((0+C23)*9))+(INT((0+C23)*5)))*0.1,0)+FLOOR(((IF((0+C23)<=200, 910, IF((0+C23)<=400, 1600, 7300)))+(INT(IF((0+C23)<=200, (0+C23)*120, IF((0+C23)<=400, 24000+((0+C23)-200)*214.6, 66920+((0+C23)-400)*307.3)))+INT(MAX((0+C23)-1000,0)*(736.2-307.3)))+(INT((0+C23)*9))+(INT((0+C23)*5)))*0.027,10),10) -> 729950 | BC6: =FLOOR(((IF(MAX(0+C23-C37,0)<=200, 910, IF(MAX(0+C23-C37,0)<=400, 1600, 7300)))+(INT(IF(MAX(0+C23-C37,0)<=200, MAX(0+C23-C37,0)*120, IF(MAX(0+C23-C37,0)<=400, 24000+(MAX(0+C23-C37,0)-200)*214.6, 66920+(MAX(0+C23-C37,0)-400)*307.3)))+INT(MAX(MAX(0+C23-C37,0)-1000,0)*(736.2-307.3)))+(INT(MAX(0+C23-C37,0)*9))+(INT(MAX(0+C23-C37,0)*5)))+ROUND(((IF(MAX(0+C23-C37,0)<=200, 910, IF(MAX(0+C23-C37,0)<=400, 1600, 7300)))+(INT(IF(MAX(0+C23-C37,0)<=200, MAX(0+C23-C37,0)*120, IF(MAX(0+C23-C37,0)<=400, 24000+(MAX(0+C23-C37,0)-200)*214.6, 66920+(MAX(0+C23-C37,0)-400)*307.3)))+INT(MAX(MAX(0+C23-C37,0)-1000,0)*(736.2-307.3)))+(INT(MAX(0+C23-C37,0)*9))+(INT(MAX(0+C23-C37,0)*5)))*0.1,0)+FLOOR(((IF(MAX(0+C23-C37,0)<=200, 910, IF(MAX(0+C23-C37,0)<=400, 1600, 7300)))+(INT(IF(MAX(0+C23-C37,0)<=200, MAX(0+C23-C37,0)*120, IF(MAX(0+C23-C37,0)<=400, 24000+(MAX(0+C23-C37,0)-200)*214.6, 66920+(MAX(0+C23-C37,0)-400)*307.3)))+INT(MAX(MAX(0+C23-C37,0)-1000,0)*(736.2-307.3)))+(INT(MAX(0+C23-C37,0)*9))+(INT(MAX(0+C23-C37,0)*5)))*0.027,10),10) -> 729950 | BD6: =FLOOR((($C$170*3)+(ROUNDDOWN(0*43.37%*138.7 + 0*28.76%*184.7 + 0*27.87%*220.5 + C23*30%*138.7 + C23*30%*184.7 + C23*40%*220.5, 0)+INT(MAX((0+C23)-1000,0)*(736.2-IF((0+C23)=0,0,(ROUNDDOWN(0*43.37%*138.7 + 0*28.76%*184.7 + 0*27.87%*220.5 + C23*30%*138.7 + C23*30%*184.7 + C23*40%*220.5, 0))/(0+C23)))))+(INT((0+C23)*9))+(INT((0+C23)*5)))+ROUND((($C$170*3)+(ROUNDDOWN(0*43.37%*138.7 + 0*28.76%*184.7 + 0*27.87%*220.5 + C23*30%*138.7 + C23*30%*184.7 + C23*40%*220.5, 0)+INT(MAX((0+C23)-1000,0)*(736.2-IF((0+C23)=0,0,(ROUNDDOWN(0*43.37%*138.7 + 0*28.76%*184.7 + 0*27.87%*220.5 + C23*30%*138.7 + C23*30%*184.7 + C23*40%*220.5, 0))/(0+C23)))))+(INT((0+C23)*9))+(INT((0+C23)*5)))*0.1,0)+FLOOR((($C$170*3)+(ROUNDDOWN(0*43.37%*138.7 + 0*28.76%*184.7 + 0*27.87%*220.5 + C23*30%*138.7 + C23*30%*184.7 + C23*40%*220.5, 0)+INT(MAX((0+C23)-1000,0)*(736.2-IF((0+C23)=0,0,(ROUNDDOWN(0*43.37%*138.7 + 0*28.76%*184.7 + 0*27.87%*220.5 + C23*30%*138.7 + C23*30%*184.7 + C23*40%*220.5, 0))/(0+C23)))))+(INT((0+C23)*9))+(INT((0+C23)*5)))*0.027,10),10) -> 661820 | BE6: =FLOOR((($C$170*3)+(ROUNDDOWN(MAX(0*43.37% + C23*30% - C37*0.0062%,0)*138.7 + MAX(0*28.76% + C23*30% - C37*95.4981%,0)*184.7 + MAX(0*27.87% + C23*40% - C37*4.4957%,0)*220.5,0)+INT(MAX(MAX(0+C23-C37,0)-1000,0)*(736.2-IF(MAX(0+C23-C37,0)=0,0,(ROUNDDOWN(MAX(0*43.37% + C23*30% - C37*0.0062%,0)*138.7 + MAX(0*28.76% + C23*30% - C37*95.4981%,0)*184.7 + MAX(0*27.87% + C23*40% - C37*4.4957%,0)*220.5,0))/MAX(0+C23-C37,0)))))+(INT(MAX(0+C23-C37,0)*9))+(INT(MAX(0+C23-C37,0)*5)))+ROUND((($C$170*3)+(ROUNDDOWN(MAX(0*43.37% + C23*30% - C37*0.0062%,0)*138.7 + MAX(0*28.76% + C23*30% - C37*95.4981%,0)*184.7 + MAX(0*27.87% + C23*40% - C37*4.4957%,0)*220.5,0)+INT(MAX(MAX(0+C23-C37,0)-1000,0)*(736.2-IF(MAX(0+C23-C37,0)=0,0,(ROUNDDOWN(MAX(0*43.37% + C23*30% - C37*0.0062%,0)*138.7 + MAX(0*28.76% + C23*30% - C37*95.4981%,0)*184.7 + MAX(0*27.87% + C23*40% - C37*4.4957%,0)*220.5,0))/MAX(0+C23-C37,0)))))+(INT(MAX(0+C23-C37,0)*9))+(INT(MAX(0+C23-C37,0)*5)))*0.1,0)+FLOOR((($C$170*3)+(ROUNDDOWN(MAX(0*43.37% + C23*30% - C37*0.0062%,0)*138.7 + MAX(0*28.76% + C23*30% - C37*95.4981%,0)*184.7 + MAX(0*27.87% + C23*40% - C37*4.4957%,0)*220.5,0)+INT(MAX(MAX(0+C23-C37,0)-1000,0)*(736.2-IF(MAX(0+C23-C37,0)=0,0,(ROUNDDOWN(MAX(0*43.37% + C23*30% - C37*0.0062%,0)*138.7 + MAX(0*28.76% + C23*30% - C37*95.4981%,0)*184.7 + MAX(0*27.87% + C23*40% - C37*4.4957%,0)*220.5,0))/MAX(0+C23-C37,0)))))+(INT(MAX(0+C23-C37,0)*9))+(INT(MAX(0+C23-C37,0)*5)))*0.027,10),10) -> 661820
B7: 201~400kWh 사용 | C7: 1600 | D7: 다음 200kWh까지 | E7: 214.6 | I7: 2 | J7: =IF((Sheet2!D54+C24)<=200, 910, IF((Sheet2!D54+C24)<=400, 1600, 7300)) -> 7300 | K7: =INT(IF((Sheet2!D54+C24)<=200, (Sheet2!D54+C24)*120, IF((Sheet2!D54+C24)<=400, 24000+((Sheet2!D54+C24)-200)*214.6, 66920+((Sheet2!D54+C24)-400)*307.3)))+INT(MAX((Sheet2!D54+C24)-1000,0)*(736.2-307.3)) -> 1393831 | L7: =INT((Sheet2!D54+C24)*9) -> 22967 | M7: =INT((Sheet2!D54+C24)*5) -> 12759 | N7: =SUM(J7:M7) -> 1436857 | O7: =ROUND(N7*0.1, 0) -> 143686 | P7: =FLOOR(N7*0.027, 10) -> 38790 | Q7: =FLOOR(N7+O7+P7, 10) -> 1619330 | R7: =MAX(Q7-BB7,0) -> 880440 | AK7: 세종특별자치시 | AM7: 53.295975 | AN7: 80.016552 | AO7: 89.537238 | AP7: 109.34271 | AQ7: 100.67018 | AR7: 99.02736 | AS7: 102.56514 | AT7: 69.166332 | AU7: 55.0152 | AV7: 69.876945 | AW7: 67.62285 | AX7: 50.216652 | BA7: 2 | BB7: =FLOOR(((IF((0+C24)<=200, 910, IF((0+C24)<=400, 1600, 7300)))+(INT(IF((0+C24)<=200, (0+C24)*120, IF((0+C24)<=400, 24000+((0+C24)-200)*214.6, 66920+((0+C24)-400)*307.3)))+INT(MAX((0+C24)-1000,0)*(736.2-307.3)))+(INT((0+C24)*9))+(INT((0+C24)*5)))+ROUND(((IF((0+C24)<=200, 910, IF((0+C24)<=400, 1600, 7300)))+(INT(IF((0+C24)<=200, (0+C24)*120, IF((0+C24)<=400, 24000+((0+C24)-200)*214.6, 66920+((0+C24)-400)*307.3)))+INT(MAX((0+C24)-1000,0)*(736.2-307.3)))+(INT((0+C24)*9))+(INT((0+C24)*5)))*0.1,0)+FLOOR(((IF((0+C24)<=200, 910, IF((0+C24)<=400, 1600, 7300)))+(INT(IF((0+C24)<=200, (0+C24)*120, IF((0+C24)<=400, 24000+((0+C24)-200)*214.6, 66920+((0+C24)-400)*307.3)))+INT(MAX((0+C24)-1000,0)*(736.2-307.3)))+(INT((0+C24)*9))+(INT((0+C24)*5)))*0.027,10),10) -> 738890 | BC7: =FLOOR(((IF(MAX(0+C24-C38,0)<=200, 910, IF(MAX(0+C24-C38,0)<=400, 1600, 7300)))+(INT(IF(MAX(0+C24-C38,0)<=200, MAX(0+C24-C38,0)*120, IF(MAX(0+C24-C38,0)<=400, 24000+(MAX(0+C24-C38,0)-200)*214.6, 66920+(MAX(0+C24-C38,0)-400)*307.3)))+INT(MAX(MAX(0+C24-C38,0)-1000,0)*(736.2-307.3)))+(INT(MAX(0+C24-C38,0)*9))+(INT(MAX(0+C24-C38,0)*5)))+ROUND(((IF(MAX(0+C24-C38,0)<=200, 910, IF(MAX(0+C24-C38,0)<=400, 1600, 7300)))+(INT(IF(MAX(0+C24-C38,0)<=200, MAX(0+C24-C38,0)*120, IF(MAX(0+C24-C38,0)<=400, 24000+(MAX(0+C24-C38,0)-200)*214.6, 66920+(MAX(0+C24-C38,0)-400)*307.3)))+INT(MAX(MAX(0+C24-C38,0)-1000,0)*(736.2-307.3)))+(INT(MAX(0+C24-C38,0)*9))+(INT(MAX(0+C24-C38,0)*5)))*0.1,0)+FLOOR(((IF(MAX(0+C24-C38,0)<=200, 910, IF(MAX(0+C24-C38,0)<=400, 1600, 7300)))+(INT(IF(MAX(0+C24-C38,0)<=200, MAX(0+C24-C38,0)*120, IF(MAX(0+C24-C38,0)<=400, 24000+(MAX(0+C24-C38,0)-200)*214.6, 66920+(MAX(0+C24-C38,0)-400)*307.3)))+INT(MAX(MAX(0+C24-C38,0)-1000,0)*(736.2-307.3)))+(INT(MAX(0+C24-C38,0)*9))+(INT(MAX(0+C24-C38,0)*5)))*0.027,10),10) -> 738890 | BD7: =FLOOR((($C$170*3)+(ROUNDDOWN(0*44.03%*138.7 + 0*28.8%*184.7 + 0*27.16%*220.5 + C24*30%*138.7 + C24*30%*184.7 + C24*40%*220.5, 0)+INT(MAX((0+C24)-1000,0)*(736.2-IF((0+C24)=0,0,(ROUNDDOWN(0*44.03%*138.7 + 0*28.8%*184.7 + 0*27.16%*220.5 + C24*30%*138.7 + C24*30%*184.7 + C24*40%*220.5, 0))/(0+C24)))))+(INT((0+C24)*9))+(INT((0+C24)*5)))+ROUND((($C$170*3)+(ROUNDDOWN(0*44.03%*138.7 + 0*28.8%*184.7 + 0*27.16%*220.5 + C24*30%*138.7 + C24*30%*184.7 + C24*40%*220.5, 0)+INT(MAX((0+C24)-1000,0)*(736.2-IF((0+C24)=0,0,(ROUNDDOWN(0*44.03%*138.7 + 0*28.8%*184.7 + 0*27.16%*220.5 + C24*30%*138.7 + C24*30%*184.7 + C24*40%*220.5, 0))/(0+C24)))))+(INT((0+C24)*9))+(INT((0+C24)*5)))*0.1,0)+FLOOR((($C$170*3)+(ROUNDDOWN(0*44.03%*138.7 + 0*28.8%*184.7 + 0*27.16%*220.5 + C24*30%*138.7 + C24*30%*184.7 + C24*40%*220.5, 0)+INT(MAX((0+C24)-1000,0)*(736.2-IF((0+C24)=0,0,(ROUNDDOWN(0*44.03%*138.7 + 0*28.8%*184.7 + 0*27.16%*220.5 + C24*30%*138.7 + C24*30%*184.7 + C24*40%*220.5, 0))/(0+C24)))))+(INT((0+C24)*9))+(INT((0+C24)*5)))*0.027,10),10) -> 670760 | BE7: =FLOOR((($C$170*3)+(ROUNDDOWN(MAX(0*44.03% + C24*30% - C38*0.1791%,0)*138.7 + MAX(0*28.8% + C24*30% - C38*92.1596%,0)*184.7 + MAX(0*27.16% + C24*40% - C38*7.6613%,0)*220.5,0)+INT(MAX(MAX(0+C24-C38,0)-1000,0)*(736.2-IF(MAX(0+C24-C38,0)=0,0,(ROUNDDOWN(MAX(0*44.03% + C24*30% - C38*0.1791%,0)*138.7 + MAX(0*28.8% + C24*30% - C38*92.1596%,0)*184.7 + MAX(0*27.16% + C24*40% - C38*7.6613%,0)*220.5,0))/MAX(0+C24-C38,0)))))+(INT(MAX(0+C24-C38,0)*9))+(INT(MAX(0+C24-C38,0)*5)))+ROUND((($C$170*3)+(ROUNDDOWN(MAX(0*44.03% + C24*30% - C38*0.1791%,0)*138.7 + MAX(0*28.8% + C24*30% - C38*92.1596%,0)*184.7 + MAX(0*27.16% + C24*40% - C38*7.6613%,0)*220.5,0)+INT(MAX(MAX(0+C24-C38,0)-1000,0)*(736.2-IF(MAX(0+C24-C38,0)=0,0,(ROUNDDOWN(MAX(0*44.03% + C24*30% - C38*0.1791%,0)*138.7 + MAX(0*28.8% + C24*30% - C38*92.1596%,0)*184.7 + MAX(0*27.16% + C24*40% - C38*7.6613%,0)*220.5,0))/MAX(0+C24-C38,0)))))+(INT(MAX(0+C24-C38,0)*9))+(INT(MAX(0+C24-C38,0)*5)))*0.1,0)+FLOOR((($C$170*3)+(ROUNDDOWN(MAX(0*44.03% + C24*30% - C38*0.1791%,0)*138.7 + MAX(0*28.8% + C24*30% - C38*92.1596%,0)*184.7 + MAX(0*27.16% + C24*40% - C38*7.6613%,0)*220.5,0)+INT(MAX(MAX(0+C24-C38,0)-1000,0)*(736.2-IF(MAX(0+C24-C38,0)=0,0,(ROUNDDOWN(MAX(0*44.03% + C24*30% - C38*0.1791%,0)*138.7 + MAX(0*28.8% + C24*30% - C38*92.1596%,0)*184.7 + MAX(0*27.16% + C24*40% - C38*7.6613%,0)*220.5,0))/MAX(0+C24-C38,0)))))+(INT(MAX(0+C24-C38,0)*9))+(INT(MAX(0+C24-C38,0)*5)))*0.027,10),10) -> 670760
B8: 400kWh초과 사용 | C8: 7300 | D8: 400kWh초과 | E8: 307.3 | G8: =(120*200)+(214.6*200) -> 66920 | I8: 3 | J8: =IF((Sheet2!E54+C25)<=200, 910, IF((Sheet2!E54+C25)<=400, 1600, 7300)) -> 7300 | K8: =INT(IF((Sheet2!E54+C25)<=200, (Sheet2!E54+C25)*120, IF((Sheet2!E54+C25)<=400, 24000+((Sheet2!E54+C25)-200)*214.6, 66920+((Sheet2!E54+C25)-400)*307.3))) -> 593764 | L8: =INT((Sheet2!E54+C25)*9) -> 19029 | M8: =INT((Sheet2!E54+C25)*5) -> 10572 | N8: =SUM(J8:M8) -> 630665 | O8: =ROUND(N8*0.1, 0) -> 63067 | P8: =FLOOR(N8*0.027, 10) -> 17020 | Q8: =FLOOR(N8+O8+P8, 10) -> 710750 | R8: =MAX(Q8-BB8,0) -> 290130 | AK8: 대전광역시 | AM8: 55.427814 | AN8: 81.30024 | AO8: 97.353981 | AP8: 110.71809 | AQ8: 99.012078 | AR8: 99.48582 | AS8: 106.35508 | AT8: 72.008784 | AU8: 62.35056 | AV8: 72.956268 | AW8: 70.60284 | AX8: 55.901556 | BA8: 3 | BB8: =FLOOR(((IF((0+C25)<=200, 910, IF((0+C25)<=400, 1600, 7300)))+(INT(IF((0+C25)<=200, (0+C25)*120, IF((0+C25)<=400, 24000+((0+C25)-200)*214.6, 66920+((0+C25)-400)*307.3))))+(INT((0+C25)*9))+(INT((0+C25)*5)))+ROUND(((IF((0+C25)<=200, 910, IF((0+C25)<=400, 1600, 7300)))+(INT(IF((0+C25)<=200, (0+C25)*120, IF((0+C25)<=400, 24000+((0+C25)-200)*214.6, 66920+((0+C25)-400)*307.3))))+(INT((0+C25)*9))+(INT((0+C25)*5)))*0.1,0)+FLOOR(((IF((0+C25)<=200, 910, IF((0+C25)<=400, 1600, 7300)))+(INT(IF((0+C25)<=200, (0+C25)*120, IF((0+C25)<=400, 24000+((0+C25)-200)*214.6, 66920+((0+C25)-400)*307.3))))+(INT((0+C25)*9))+(INT((0+C25)*5)))*0.027,10),10) -> 420620 | BC8: =FLOOR(((IF(MAX(0+C25-C39,0)<=200, 910, IF(MAX(0+C25-C39,0)<=400, 1600, 7300)))+(INT(IF(MAX(0+C25-C39,0)<=200, MAX(0+C25-C39,0)*120, IF(MAX(0+C25-C39,0)<=400, 24000+(MAX(0+C25-C39,0)-200)*214.6, 66920+(MAX(0+C25-C39,0)-400)*307.3))))+(INT(MAX(0+C25-C39,0)*9))+(INT(MAX(0+C25-C39,0)*5)))+ROUND(((IF(MAX(0+C25-C39,0)<=200, 910, IF(MAX(0+C25-C39,0)<=400, 1600, 7300)))+(INT(IF(MAX(0+C25-C39,0)<=200, MAX(0+C25-C39,0)*120, IF(MAX(0+C25-C39,0)<=400, 24000+(MAX(0+C25-C39,0)-200)*214.6, 66920+(MAX(0+C25-C39,0)-400)*307.3))))+(INT(MAX(0+C25-C39,0)*9))+(INT(MAX(0+C25-C39,0)*5)))*0.1,0)+FLOOR(((IF(MAX(0+C25-C39,0)<=200, 910, IF(MAX(0+C25-C39,0)<=400, 1600, 7300)))+(INT(IF(MAX(0+C25-C39,0)<=200, MAX(0+C25-C39,0)*120, IF(MAX(0+C25-C39,0)<=400, 24000+(MAX(0+C25-C39,0)-200)*214.6, 66920+(MAX(0+C25-C39,0)-400)*307.3))))+(INT(MAX(0+C25-C39,0)*9))+(INT(MAX(0+C25-C39,0)*5)))*0.027,10),10) -> 420620 | BD8: =FLOOR((($C$170*3)+(ROUNDDOWN(0*44.16%*125.8 + 0*28.26%*153.8 + 0*27.58%*172.4 + C25*30%*125.8 + C25*30%*153.8 + C25*40%*172.4, 0))+(INT((0+C25)*9))+(INT((0+C25)*5)))+ROUND((($C$170*3)+(ROUNDDOWN(0*44.16%*125.8 + 0*28.26%*153.8 + 0*27.58%*172.4 + C25*30%*125.8 + C25*30%*153.8 + C25*40%*172.4, 0))+(INT((0+C25)*9))+(INT((0+C25)*5)))*0.1,0)+FLOOR((($C$170*3)+(ROUNDDOWN(0*44.16%*125.8 + 0*28.26%*153.8 + 0*27.58%*172.4 + C25*30%*125.8 + C25*30%*153.8 + C25*40%*172.4, 0))+(INT((0+C25)*9))+(INT((0+C25)*5)))*0.027,10),10) -> 261480 | BE8: =FLOOR((($C$170*3)+(ROUNDDOWN(MAX(0*44.16% + C25*30% - C39*1.149%,0)*125.8 + MAX(0*28.26% + C25*30% - C39*89.637%,0)*153.8 + MAX(0*27.58% + C25*40% - C39*9.2139%,0)*172.4,0))+(INT(MAX(0+C25-C39,0)*9))+(INT(MAX(0+C25-C39,0)*5)))+ROUND((($C$170*3)+(ROUNDDOWN(MAX(0*44.16% + C25*30% - C39*1.149%,0)*125.8 + MAX(0*28.26% + C25*30% - C39*89.637%,0)*153.8 + MAX(0*27.58% + C25*40% - C39*9.2139%,0)*172.4,0))+(INT(MAX(0+C25-C39,0)*9))+(INT(MAX(0+C25-C39,0)*5)))*0.1,0)+FLOOR((($C$170*3)+(ROUNDDOWN(MAX(0*44.16% + C25*30% - C39*1.149%,0)*125.8 + MAX(0*28.26% + C25*30% - C39*89.637%,0)*153.8 + MAX(0*27.58% + C25*40% - C39*9.2139%,0)*172.4,0))+(INT(MAX(0+C25-C39,0)*9))+(INT(MAX(0+C25-C39,0)*5)))*0.027,10),10) -> 261480
I9: 4 | J9: =IF((Sheet2!F54+C26)<=200, 910, IF((Sheet2!F54+C26)<=400, 1600, 7300)) -> 7300 | K9: =INT(IF((Sheet2!F54+C26)<=200, (Sheet2!F54+C26)*120, IF((Sheet2!F54+C26)<=400, 24000+((Sheet2!F54+C26)-200)*214.6, 66920+((Sheet2!F54+C26)-400)*307.3))) -> 448773 | L9: =INT((Sheet2!F54+C26)*9) -> 14783 | M9: =INT((Sheet2!F54+C26)*5) -> 8213 | N9: =SUM(J9:M9) -> 479069 | O9: =ROUND(N9*0.1, 0) -> 47907 | P9: =FLOOR(N9*0.027, 10) -> 12930 | Q9: =FLOOR(N9+O9+P9, 10) -> 539900 | R9: =MAX(Q9-BB9,0) -> 117450 | AK9: 대구광역시 | AM9: 64.902654 | AN9: 88.146576 | AO9: 90.721593 | AP9: 111.86424 | AQ9: 102.80201 | AR9: 102.69504 | AS9: 110.61876 | AT9: 70.350687 | AU9: 51.57675 | AV9: 75.79872 | AW9: 73.3536 | AX9: 60.638976 | BA9: 4 | BB9: =FLOOR(((IF((0+C26)<=200, 910, IF((0+C26)<=400, 1600, 7300)))+(INT(IF((0+C26)<=200, (0+C26)*120, IF((0+C26)<=400, 24000+((0+C26)-200)*214.6, 66920+((0+C26)-400)*307.3))))+(INT((0+C26)*9))+(INT((0+C26)*5)))+ROUND(((IF((0+C26)<=200, 910, IF((0+C26)<=400, 1600, 7300)))+(INT(IF((0+C26)<=200, (0+C26)*120, IF((0+C26)<=400, 24000+((0+C26)-200)*214.6, 66920+((0+C26)-400)*307.3))))+(INT((0+C26)*9))+(INT((0+C26)*5)))*0.1,0)+FLOOR(((IF((0+C26)<=200, 910, IF((0+C26)<=400, 1600, 7300)))+(INT(IF((0+C26)<=200, (0+C26)*120, IF((0+C26)<=400, 24000+((0+C26)-200)*214.6, 66920+((0+C26)-400)*307.3))))+(INT((0+C26)*9))+(INT((0+C26)*5)))*0.027,10),10) -> 422450 | BC9: =FLOOR(((IF(MAX(0+C26-C40,0)<=200, 910, IF(MAX(0+C26-C40,0)<=400, 1600, 7300)))+(INT(IF(MAX(0+C26-C40,0)<=200, MAX(0+C26-C40,0)*120, IF(MAX(0+C26-C40,0)<=400, 24000+(MAX(0+C26-C40,0)-200)*214.6, 66920+(MAX(0+C26-C40,0)-400)*307.3))))+(INT(MAX(0+C26-C40,0)*9))+(INT(MAX(0+C26-C40,0)*5)))+ROUND(((IF(MAX(0+C26-C40,0)<=200, 910, IF(MAX(0+C26-C40,0)<=400, 1600, 7300)))+(INT(IF(MAX(0+C26-C40,0)<=200, MAX(0+C26-C40,0)*120, IF(MAX(0+C26-C40,0)<=400, 24000+(MAX(0+C26-C40,0)-200)*214.6, 66920+(MAX(0+C26-C40,0)-400)*307.3))))+(INT(MAX(0+C26-C40,0)*9))+(INT(MAX(0+C26-C40,0)*5)))*0.1,0)+FLOOR(((IF(MAX(0+C26-C40,0)<=200, 910, IF(MAX(0+C26-C40,0)<=400, 1600, 7300)))+(INT(IF(MAX(0+C26-C40,0)<=200, MAX(0+C26-C40,0)*120, IF(MAX(0+C26-C40,0)<=400, 24000+(MAX(0+C26-C40,0)-200)*214.6, 66920+(MAX(0+C26-C40,0)-400)*307.3))))+(INT(MAX(0+C26-C40,0)*9))+(INT(MAX(0+C26-C40,0)*5)))*0.027,10),10) -> 422450 | BD9: =FLOOR((($C$170*3)+(ROUNDDOWN(0*42.51%*125.8 + 0*27.79%*153.8 + 0*29.7%*172.4 + C26*30%*125.8 + C26*30%*153.8 + C26*40%*172.4, 0))+(INT((0+C26)*9))+(INT((0+C26)*5)))+ROUND((($C$170*3)+(ROUNDDOWN(0*42.51%*125.8 + 0*27.79%*153.8 + 0*29.7%*172.4 + C26*30%*125.8 + C26*30%*153.8 + C26*40%*172.4, 0))+(INT((0+C26)*9))+(INT((0+C26)*5)))*0.1,0)+FLOOR((($C$170*3)+(ROUNDDOWN(0*42.51%*125.8 + 0*27.79%*153.8 + 0*29.7%*172.4 + C26*30%*125.8 + C26*30%*153.8 + C26*40%*172.4, 0))+(INT((0+C26)*9))+(INT((0+C26)*5)))*0.027,10),10) -> 262420 | BE9: =FLOOR((($C$170*3)+(ROUNDDOWN(MAX(0*42.51% + C26*30% - C40*2.6448%,0)*125.8 + MAX(0*27.79% + C26*30% - C40*86.8176%,0)*153.8 + MAX(0*29.7% + C26*40% - C40*10.5375%,0)*172.4,0))+(INT(MAX(0+C26-C40,0)*9))+(INT(MAX(0+C26-C40,0)*5)))+ROUND((($C$170*3)+(ROUNDDOWN(MAX(0*42.51% + C26*30% - C40*2.6448%,0)*125.8 + MAX(0*27.79% + C26*30% - C40*86.8176%,0)*153.8 + MAX(0*29.7% + C26*40% - C40*10.5375%,0)*172.4,0))+(INT(MAX(0+C26-C40,0)*9))+(INT(MAX(0+C26-C40,0)*5)))*0.1,0)+FLOOR((($C$170*3)+(ROUNDDOWN(MAX(0*42.51% + C26*30% - C40*2.6448%,0)*125.8 + MAX(0*27.79% + C26*30% - C40*86.8176%,0)*153.8 + MAX(0*29.7% + C26*40% - C40*10.5375%,0)*172.4,0))+(INT(MAX(0+C26-C40,0)*9))+(INT(MAX(0+C26-C40,0)*5)))*0.027,10),10) -> 262420
B10: 1. 기타계절 : 1월 1일~6월 30일, 9월 1일~12월 31일 | I10: 5 | J10: =IF((Sheet2!G54+C27)<=200, 910, IF((Sheet2!G54+C27)<=400, 1600, 7300)) -> 7300 | K10: =INT(IF((Sheet2!G54+C27)<=200, (Sheet2!G54+C27)*120, IF((Sheet2!G54+C27)<=400, 24000+((Sheet2!G54+C27)-200)*214.6, 66920+((Sheet2!G54+C27)-400)*307.3))) -> 381632 | L10: =INT((Sheet2!G54+C27)*9) -> 12817 | M10: =INT((Sheet2!G54+C27)*5) -> 7120 | N10: =SUM(J10:M10) -> 408869 | O10: =ROUND(N10*0.1, 0) -> 40887 | P10: =FLOOR(N10*0.027, 10) -> 11030 | Q10: =FLOOR(N10+O10+P10, 10) -> 460780 | R10: =MAX(Q10-BB10,0) -> 67640 | AK10: 부산광역시 | AM10: 68.455719 | AN10: 84.081564 | AO10: 90.484722 | AP10: 105.21657 | AQ10: 96.643368 | AR10: 97.65198 | AS10: 107.30256 | AT10: 70.113816 | AU10: 59.14134 | AV10: 74.140623 | AW10: 71.74899 | AX10: 61.112718 | BA10: 5 | BB10: =FLOOR(((IF((0+C27)<=200, 910, IF((0+C27)<=400, 1600, 7300)))+(INT(IF((0+C27)<=200, (0+C27)*120, IF((0+C27)<=400, 24000+((0+C27)-200)*214.6, 66920+((0+C27)-400)*307.3))))+(INT((0+C27)*9))+(INT((0+C27)*5)))+ROUND(((IF((0+C27)<=200, 910, IF((0+C27)<=400, 1600, 7300)))+(INT(IF((0+C27)<=200, (0+C27)*120, IF((0+C27)<=400, 24000+((0+C27)-200)*214.6, 66920+((0+C27)-400)*307.3))))+(INT((0+C27)*9))+(INT((0+C27)*5)))*0.1,0)+FLOOR(((IF((0+C27)<=200, 910, IF((0+C27)<=400, 1600, 7300)))+(INT(IF((0+C27)<=200, (0+C27)*120, IF((0+C27)<=400, 24000+((0+C27)-200)*214.6, 66920+((0+C27)-400)*307.3))))+(INT((0+C27)*9))+(INT((0+C27)*5)))*0.027,10),10) -> 393140 | BC10: =FLOOR(((IF(MAX(0+C27-C41,0)<=200, 910, IF(MAX(0+C27-C41,0)<=400, 1600, 7300)))+(INT(IF(MAX(0+C27-C41,0)<=200, MAX(0+C27-C41,0)*120, IF(MAX(0+C27-C41,0)<=400, 24000+(MAX(0+C27-C41,0)-200)*214.6, 66920+(MAX(0+C27-C41,0)-400)*307.3))))+(INT(MAX(0+C27-C41,0)*9))+(INT(MAX(0+C27-C41,0)*5)))+ROUND(((IF(MAX(0+C27-C41,0)<=200, 910, IF(MAX(0+C27-C41,0)<=400, 1600, 7300)))+(INT(IF(MAX(0+C27-C41,0)<=200, MAX(0+C27-C41,0)*120, IF(MAX(0+C27-C41,0)<=400, 24000+(MAX(0+C27-C41,0)-200)*214.6, 66920+(MAX(0+C27-C41,0)-400)*307.3))))+(INT(MAX(0+C27-C41,0)*9))+(INT(MAX(0+C27-C41,0)*5)))*0.1,0)+FLOOR(((IF(MAX(0+C27-C41,0)<=200, 910, IF(MAX(0+C27-C41,0)<=400, 1600, 7300)))+(INT(IF(MAX(0+C27-C41,0)<=200, MAX(0+C27-C41,0)*120, IF(MAX(0+C27-C41,0)<=400, 24000+(MAX(0+C27-C41,0)-200)*214.6, 66920+(MAX(0+C27-C41,0)-400)*307.3))))+(INT(MAX(0+C27-C41,0)*9))+(INT(MAX(0+C27-C41,0)*5)))*0.027,10),10) -> 393140 | BD10: =FLOOR((($C$170*3)+(ROUNDDOWN(0*38.44%*125.8 + 0*30.44%*153.8 + 0*31.12%*172.4 + C27*30%*125.8 + C27*30%*153.8 + C27*40%*172.4, 0))+(INT((0+C27)*9))+(INT((0+C27)*5)))+ROUND((($C$170*3)+(ROUNDDOWN(0*38.44%*125.8 + 0*30.44%*153.8 + 0*31.12%*172.4 + C27*30%*125.8 + C27*30%*153.8 + C27*40%*172.4, 0))+(INT((0+C27)*9))+(INT((0+C27)*5)))*0.1,0)+FLOOR((($C$170*3)+(ROUNDDOWN(0*38.44%*125.8 + 0*30.44%*153.8 + 0*31.12%*172.4 + C27*30%*125.8 + C27*30%*153.8 + C27*40%*172.4, 0))+(INT((0+C27)*9))+(INT((0+C27)*5)))*0.027,10),10) -> 247210 | BE10: =FLOOR((($C$170*3)+(ROUNDDOWN(MAX(0*38.44% + C27*30% - C41*4.1831%,0)*125.8 + MAX(0*30.44% + C27*30% - C41*84.4735%,0)*153.8 + MAX(0*31.12% + C27*40% - C41*11.3434%,0)*172.4,0))+(INT(MAX(0+C27-C41,0)*9))+(INT(MAX(0+C27-C41,0)*5)))+ROUND((($C$170*3)+(ROUNDDOWN(MAX(0*38.44% + C27*30% - C41*4.1831%,0)*125.8 + MAX(0*30.44% + C27*30% - C41*84.4735%,0)*153.8 + MAX(0*31.12% + C27*40% - C41*11.3434%,0)*172.4,0))+(INT(MAX(0+C27-C41,0)*9))+(INT(MAX(0+C27-C41,0)*5)))*0.1,0)+FLOOR((($C$170*3)+(ROUNDDOWN(MAX(0*38.44% + C27*30% - C41*4.1831%,0)*125.8 + MAX(0*30.44% + C27*30% - C41*84.4735%,0)*153.8 + MAX(0*31.12% + C27*40% - C41*11.3434%,0)*172.4,0))+(INT(MAX(0+C27-C41,0)*9))+(INT(MAX(0+C27-C41,0)*5)))*0.027,10),10) -> 247210
B11: 2. 슈퍼유저요금 : 동계(12월 1일~2월 말일) 1,000kWh초과 전력량요금은 736.2원/kWh 적용 | I11: 6 | J11: =IF((Sheet2!H54+C28)<=200, 910, IF((Sheet2!H54+C28)<=400, 1600, 7300)) -> 7300 | K11: =INT(IF((Sheet2!H54+C28)<=200, (Sheet2!H54+C28)*120, IF((Sheet2!H54+C28)<=400, 24000+((Sheet2!H54+C28)-200)*214.6, 66920+((Sheet2!H54+C28)-400)*307.3))) -> 388753 | L11: =INT((Sheet2!H54+C28)*9) -> 13025 | M11: =INT((Sheet2!H54+C28)*5) -> 7236 | N11: =SUM(J11:M11) -> 416314 | O11: =ROUND(N11*0.1, 0) -> 41631 | P11: =FLOOR(N11*0.027, 10) -> 11240 | Q11: =FLOOR(N11+O11+P11, 10) -> 469180 | R11: =MAX(Q11-BB11,0) -> 46250 | AK11: 울산광역시 | AM11: 68.455719 | AN11: 84.081564 | AO11: 90.484722 | AP11: 105.21657 | AQ11: 96.643368 | AR11: 97.65198 | AS11: 107.30256 | AT11: 70.113816 | AU11: 59.14134 | AV11: 74.140623 | AW11: 71.74899 | AX11: 61.112718 | BA11: 6 | BB11: =FLOOR(((IF((0+C28)<=200, 910, IF((0+C28)<=400, 1600, 7300)))+(INT(IF((0+C28)<=200, (0+C28)*120, IF((0+C28)<=400, 24000+((0+C28)-200)*214.6, 66920+((0+C28)-400)*307.3))))+(INT((0+C28)*9))+(INT((0+C28)*5)))+ROUND(((IF((0+C28)<=200, 910, IF((0+C28)<=400, 1600, 7300)))+(INT(IF((0+C28)<=200, (0+C28)*120, IF((0+C28)<=400, 24000+((0+C28)-200)*214.6, 66920+((0+C28)-400)*307.3))))+(INT((0+C28)*9))+(INT((0+C28)*5)))*0.1,0)+FLOOR(((IF((0+C28)<=200, 910, IF((0+C28)<=400, 1600, 7300)))+(INT(IF((0+C28)<=200, (0+C28)*120, IF((0+C28)<=400, 24000+((0+C28)-200)*214.6, 66920+((0+C28)-400)*307.3))))+(INT((0+C28)*9))+(INT((0+C28)*5)))*0.027,10),10) -> 422930 | BC11: =FLOOR(((IF(MAX(0+C28-C42,0)<=200, 910, IF(MAX(0+C28-C42,0)<=400, 1600, 7300)))+(INT(IF(MAX(0+C28-C42,0)<=200, MAX(0+C28-C42,0)*120, IF(MAX(0+C28-C42,0)<=400, 24000+(MAX(0+C28-C42,0)-200)*214.6, 66920+(MAX(0+C28-C42,0)-400)*307.3))))+(INT(MAX(0+C28-C42,0)*9))+(INT(MAX(0+C28-C42,0)*5)))+ROUND(((IF(MAX(0+C28-C42,0)<=200, 910, IF(MAX(0+C28-C42,0)<=400, 1600, 7300)))+(INT(IF(MAX(0+C28-C42,0)<=200, MAX(0+C28-C42,0)*120, IF(MAX(0+C28-C42,0)<=400, 24000+(MAX(0+C28-C42,0)-200)*214.6, 66920+(MAX(0+C28-C42,0)-400)*307.3))))+(INT(MAX(0+C28-C42,0)*9))+(INT(MAX(0+C28-C42,0)*5)))*0.1,0)+FLOOR(((IF(MAX(0+C28-C42,0)<=200, 910, IF(MAX(0+C28-C42,0)<=400, 1600, 7300)))+(INT(IF(MAX(0+C28-C42,0)<=200, MAX(0+C28-C42,0)*120, IF(MAX(0+C28-C42,0)<=400, 24000+(MAX(0+C28-C42,0)-200)*214.6, 66920+(MAX(0+C28-C42,0)-400)*307.3))))+(INT(MAX(0+C28-C42,0)*9))+(INT(MAX(0+C28-C42,0)*5)))*0.027,10),10) -> 422930 | BD11: =FLOOR((($C$170*3)+(ROUNDDOWN(0*31.92%*138.7 + 0*38.86%*184.7 + 0*29.22%*220.5 + C28*30%*138.7 + C28*30%*184.7 + C28*40%*220.5, 0)+INT(MAX((0+C28)-1000,0)*(736.2-IF((0+C28)=0,0,(ROUNDDOWN(0*31.92%*138.7 + 0*38.86%*184.7 + 0*29.22%*220.5 + C28*30%*138.7 + C28*30%*184.7 + C28*40%*220.5, 0))/(0+C28)))))+(INT((0+C28)*9))+(INT((0+C28)*5)))+ROUND((($C$170*3)+(ROUNDDOWN(0*31.92%*138.7 + 0*38.86%*184.7 + 0*29.22%*220.5 + C28*30%*138.7 + C28*30%*184.7 + C28*40%*220.5, 0)+INT(MAX((0+C28)-1000,0)*(736.2-IF((0+C28)=0,0,(ROUNDDOWN(0*31.92%*138.7 + 0*38.86%*184.7 + 0*29.22%*220.5 + C28*30%*138.7 + C28*30%*184.7 + C28*40%*220.5, 0))/(0+C28)))))+(INT((0+C28)*9))+(INT((0+C28)*5)))*0.1,0)+FLOOR((($C$170*3)+(ROUNDDOWN(0*31.92%*138.7 + 0*38.86%*184.7 + 0*29.22%*220.5 + C28*30%*138.7 + C28*30%*184.7 + C28*40%*220.5, 0)+INT(MAX((0+C28)-1000,0)*(736.2-IF((0+C28)=0,0,(ROUNDDOWN(0*31.92%*138.7 + 0*38.86%*184.7 + 0*29.22%*220.5 + C28*30%*138.7 + C28*30%*184.7 + C28*40%*220.5, 0))/(0+C28)))))+(INT((0+C28)*9))+(INT((0+C28)*5)))*0.027,10),10) -> 509280 | BE11: =FLOOR((($C$170*3)+(ROUNDDOWN(MAX(0*31.92% + C28*30% - C42*4.7395%,0)*138.7 + MAX(0*38.86% + C28*30% - C42*81.6742%,0)*184.7 + MAX(0*29.22% + C28*40% - C42*13.5862%,0)*220.5,0)+INT(MAX(MAX(0+C28-C42,0)-1000,0)*(736.2-IF(MAX(0+C28-C42,0)=0,0,(ROUNDDOWN(MAX(0*31.92% + C28*30% - C42*4.7395%,0)*138.7 + MAX(0*38.86% + C28*30% - C42*81.6742%,0)*184.7 + MAX(0*29.22% + C28*40% - C42*13.5862%,0)*220.5,0))/MAX(0+C28-C42,0)))))+(INT(MAX(0+C28-C42,0)*9))+(INT(MAX(0+C28-C42,0)*5)))+ROUND((($C$170*3)+(ROUNDDOWN(MAX(0*31.92% + C28*30% - C42*4.7395%,0)*138.7 + MAX(0*38.86% + C28*30% - C42*81.6742%,0)*184.7 + MAX(0*29.22% + C28*40% - C42*13.5862%,0)*220.5,0)+INT(MAX(MAX(0+C28-C42,0)-1000,0)*(736.2-IF(MAX(0+C28-C42,0)=0,0,(ROUNDDOWN(MAX(0*31.92% + C28*30% - C42*4.7395%,0)*138.7 + MAX(0*38.86% + C28*30% - C42*81.6742%,0)*184.7 + MAX(0*29.22% + C28*40% - C42*13.5862%,0)*220.5,0))/MAX(0+C28-C42,0)))))+(INT(MAX(0+C28-C42,0)*9))+(INT(MAX(0+C28-C42,0)*5)))*0.1,0)+FLOOR((($C$170*3)+(ROUNDDOWN(MAX(0*31.92% + C28*30% - C42*4.7395%,0)*138.7 + MAX(0*38.86% + C28*30% - C42*81.6742%,0)*184.7 + MAX(0*29.22% + C28*40% - C42*13.5862%,0)*220.5,0)+INT(MAX(MAX(0+C28-C42,0)-1000,0)*(736.2-IF(MAX(0+C28-C42,0)=0,0,(ROUNDDOWN(MAX(0*31.92% + C28*30% - C42*4.7395%,0)*138.7 + MAX(0*38.86% + C28*30% - C42*81.6742%,0)*184.7 + MAX(0*29.22% + C28*40% - C42*13.5862%,0)*220.5,0))/MAX(0+C28-C42,0)))))+(INT(MAX(0+C28-C42,0)*9))+(INT(MAX(0+C28-C42,0)*5)))*0.027,10),10) -> 509280
